Workbook

Sheet Cover
A1: Sales Capacity Planning
A2: Last update: May 30, 2025
A3: FOR EDUCATIONAL PURPOSES ONLY
B5: SHARE THIS DOC AND SUBSCRIBE TO GET MORE>>> | F5: CFOPilot
B7: This file is just for educational purposes and to show what a sales capacity planning model might look like Disclaimer: There might be formula mistakes and/or differences on how you need to forecast
B14: *Subscribe and get future updates to the model as I add more layers to this sales capacity model

Sheet ARR Waterfall
A1: Sales Capacity Planning Template
E3: Quarterly>>> | J3: Monthly>>> | K3: Forecast | L3: Forecast | M3: Forecast | N3: Forecast | O3: Forecast | P3: Forecast | Q3: Forecast | R3: Forecast | S3: Forecast | T3: Forecast | U3: Forecast | V3: Forecast
C4: FY25 | E4: Q1FY25 | F4: Q2FY25 | G4: Q3FY25 | H4: Q4FY25 | J4: 44950 | K4: 44981 | L4: 45009 | M4: 45040 | N4: 45070 | O4: 45101 | P4: 45131 | Q4: 45162 | R4: 45193 | S4: 45223 | T4: 45254 | U4: 45284 | V4: 44951
B5: Beginning ARR | C5: =J9 -> 25000000 | E5: =J9 -> 25000000 | F5: =E9 -> 25434800 | G5: =F9 -> 26182020 | H5: =G9 -> 27561920 | K5: =J9 -> 25000000 | L5: =K9 -> 25100920 | M5: =L9 -> 25231360 | N5: =M9 -> 25434800 | O5: =N9 -> 25639040 | P5: =O9 -> 25850660 | Q5: =P9 -> 26182020 | R5: =Q9 -> 26548020 | ... V5: =U9 -> 28948340
B6: (+) New Business ARR | C6: =sum(E6:H6) -> 5953200 | E6: =SUM(K6:M6) -> 747840 | F6: =SUM(N6:P6) -> 997776 | G6: =SUM(Q6:S6) -> 1603920 | H6: =SUM(T6:V6) -> 2603664 | K6: ='Sales Capacity'!G62-K7 -> 200736 | L6: ='Sales Capacity'!H62-L7 -> 224352 | M6: ='Sales Capacity'!I62-M7 -> 322752 | N6: ='Sales Capacity'!J62-N7 -> 283392 | O6: ='Sales Capacity'!K62-O7 -> 289296 | P6: ='Sales Capacity'!L62-P7 -> 425088 | Q6: ='Sales Capacity'!M62-Q7 -> 442800 | R6: ='Sales Capacity'!N62-R7 -> 472320 | ... V6: ='Sales Capacity'!R62-V7 -> 1074528
B7: (+) Expansion | C7: =sum(E7:H7) -> 1488300 | E7: =SUM(K7:M7) -> 186960 | F7: =SUM(N7:P7) -> 249444 | G7: =SUM(Q7:S7) -> 400980 | H7: =SUM(T7:V7) -> 650916 | K7: ='Sales Capacity'!G62*Drivers!$C$28 -> 50184 | L7: ='Sales Capacity'!H62*Drivers!$C$28 -> 56088 | M7: ='Sales Capacity'!I62*Drivers!$C$28 -> 80688 | N7: ='Sales Capacity'!J62*Drivers!$C$28 -> 70848 | O7: ='Sales Capacity'!K62*Drivers!$C$28 -> 72324 | P7: ='Sales Capacity'!L62*Drivers!$C$28 -> 106272 | Q7: ='Sales Capacity'!M62*Drivers!$C$28 -> 110700 | R7: ='Sales Capacity'!N62*Drivers!$C$28 -> 118080 | ... V7: ='Sales Capacity'!R62*Drivers!$C$28 -> 268632
B8: (-) Churn (logo & revenue) | C8: =sum(E8:H8) -> -2500000 | E8: =SUM(K8:M8) -> -500000 | F8: =SUM(N8:P8) -> -500000 | G8: =SUM(Q8:S8) -> -625000 | H8: =SUM(T8:V8) -> -875000 | K8: =-$J$9*Drivers!$C$26*Drivers!C24 -> -150000 | L8: =-$J$9*Drivers!$C$26*Drivers!D24 -> -150000 | M8: =-$J$9*Drivers!$C$26*Drivers!E24 -> -200000 | N8: =-$J$9*Drivers!$C$26*Drivers!F24 -> -150000 | O8: =-$J$9*Drivers!$C$26*Drivers!G24 -> -150000 | P8: =-$J$9*Drivers!$C$26*Drivers!H24 -> -200000 | Q8: =-$J$9*Drivers!$C$26*Drivers!I24 -> -187500 | R8: =-$J$9*Drivers!$C$26*Drivers!J24 -> -187500 | ... V8: =-$J$9*Drivers!$C$26*Drivers!N24 -> -350000
B9: Ending ARR | C9: =SUM(C5:C8) -> 29941500 | E9: =SUM(E5:E8) -> 25434800 | F9: =SUM(F5:F8) -> 26182020 | G9: =SUM(G5:G8) -> 27561920 | H9: =SUM(H5:H8) -> 29941500 | J9: 25000000 | K9: =SUM(K5:K8) -> 25100920 | L9: =SUM(L5:L8) -> 25231360 | M9: =SUM(M5:M8) -> 25434800 | N9: =SUM(N5:N8) -> 25639040 | O9: =SUM(O5:O8) -> 25850660 | P9: =SUM(P5:P8) -> 26182020 | Q9: =SUM(Q5:Q8) -> 26548020 | R9: =SUM(R5:R8) -> 26950920 | ... V9: =SUM(V5:V8) -> 29941500
B10: growth % y/y | C10: =C9/C5-1 -> 0.19766 | H10: =H9/E5-1 -> 0.19766 | V10: =V9/J9-1 -> 0.19766
B11: growth % m/m | K11: =K9/J9-1 -> 0.0040368 | L11: =L9/K9-1 -> 0.0051966223 | M11: =M9/L9-1 -> 0.0080629819 | N11: =N9/M9-1 -> 0.0080299432 | O11: =O9/N9-1 -> 0.0082538192 | P11: =P9/O9-1 -> 0.012818241 | Q11: =Q9/P9-1 -> 0.013979059 | R11: =R9/Q9-1 -> 0.015176273 | ... V11: =V9/U9-1 -> 0.034308012
B14: Attainment Forecasts
B15: FY25 Board ARR Target | C15: 31000000
B16: Current Forecast | C16: =C9 -> 29941500
B17: Excess/(Shortfall) | C17: =C16-C15 -> -1058500
B19: Forecasted New ARR | C19: =sum(C6:C7) -> 7441500
B20: Street Quota | C20: =SUM('Sales Capacity'!G55:R55) -> 9075000 | D20: *Total available quota (no overassign)
B22: Remaining overassign/(underassign) | C22: =C20-C19 -> 1633500
B23: % overassign/(underassign) | C23: =C22/C20 -> 0.18 | D23: *Before any actuals are added this will equal the overassign noted on the "Drivers" tab

Sheet Sales Capacity
G1: 45351 | H1: =EOMONTH(G1,1) -> 45382 | I1: =EOMONTH(H1,1) -> 45412 | J1: =EOMONTH(I1,1) -> 45443 | K1: =EOMONTH(J1,1) -> 45473 | L1: =EOMONTH(K1,1) -> 45504 | M1: =EOMONTH(L1,1) -> 45535 | N1: =EOMONTH(M1,1) -> 45565 | O1: =EOMONTH(N1,1) -> 45596 | ... AD1: =EOMONTH(AC1,1) -> 46053
B2: AE name | C2: Role | D2: Actual / Forecasted Start Date | E2: End Date (including forecasts) | G2: =SWITCH(MONTH(G1),2,"Q1",3,"Q1",4,"Q1",5,"Q2",6,"Q2",7,"Q2",8,"Q3",9,"Q3",10,"Q3","Q4")&"M"&SWITCH(MONTH(G1),2,"1",3,"2",4,"3",5,"1",6,"2",7,"3",8,"1",9,"2",10,"3",11,"2",12,"2",1,"3",)&"FY"&IF(MONTH(G1)=1,TEXT(G1,"yy"),TEXT(DATE(YEAR(G1)+1,MONTH(G1),DAY(G1)),"yy")) -> Q1M1FY25 | H2: =SWITCH(MONTH(H1),2,"Q1",3,"Q1",4,"Q1",5,"Q2",6,"Q2",7,"Q2",8,"Q3",9,"Q3",10,"Q3","Q4")&"M"&SWITCH(MONTH(H1),2,"1",3,"2",4,"3",5,"1",6,"2",7,"3",8,"1",9,"2",10,"3",11,"2",12,"2",1,"3",)&"FY"&IF(MONTH(H1)=1,TEXT(H1,"yy"),TEXT(DATE(YEAR(H1)+1,MONTH(H1),DAY(H1)),"yy")) -> Q1M2FY25 | I2: =SWITCH(MONTH(I1),2,"Q1",3,"Q1",4,"Q1",5,"Q2",6,"Q2",7,"Q2",8,"Q3",9,"Q3",10,"Q3","Q4")&"M"&SWITCH(MONTH(I1),2,"1",3,"2",4,"3",5,"1",6,"2",7,"3",8,"1",9,"2",10,"3",11,"2",12,"2",1,"3",)&"FY"&IF(MONTH(I1)=1,TEXT(I1,"yy"),TEXT(DATE(YEAR(I1)+1,MONTH(I1),DAY(I1)),"yy")) -> Q1M3FY25 | J2: =SWITCH(MONTH(J1),2,"Q1",3,"Q1",4,"Q1",5,"Q2",6,"Q2",7,"Q2",8,"Q3",9,"Q3",10,"Q3","Q4")&"M"&SWITCH(MONTH(J1),2,"1",3,"2",4,"3",5,"1",6,"2",7,"3",8,"1",9,"2",10,"3",11,"2",12,"2",1,"3",)&"FY"&IF(MONTH(J1)=1,TEXT(J1,"yy"),TEXT(DATE(YEAR(J1)+1,MONTH(J1),DAY(J1)),"yy")) -> Q2M1FY25 | K2: =SWITCH(MONTH(K1),2,"Q1",3,"Q1",4,"Q1",5,"Q2",6,"Q2",7,"Q2",8,"Q3",9,"Q3",10,"Q3","Q4")&"M"&SWITCH(MONTH(K1),2,"1",3,"2",4,"3",5,"1",6,"2",7,"3",8,"1",9,"2",10,"3",11,"2",12,"2",1,"3",)&"FY"&IF(MONTH(K1)=1,TEXT(K1,"yy"),TEXT(DATE(YEAR(K1)+1,MONTH(K1),DAY(K1)),"yy")) -> Q2M2FY25 | L2: =SWITCH(MONTH(L1),2,"Q1",3,"Q1",4,"Q1",5,"Q2",6,"Q2",7,"Q2",8,"Q3",9,"Q3",10,"Q3","Q4")&"M"&SWITCH(MONTH(L1),2,"1",3,"2",4,"3",5,"1",6,"2",7,"3",8,"1",9,"2",10,"3",11,"2",12,"2",1,"3",)&"FY"&IF(MONTH(L1)=1,TEXT(L1,"yy"),TEXT(DATE(YEAR(L1)+1,MONTH(L1),DAY(L1)),"yy")) -> Q2M3FY25 | M2: =SWITCH(MONTH(M1),2,"Q1",3,"Q1",4,"Q1",5,"Q2",6,"Q2",7,"Q2",8,"Q3",9,"Q3",10,"Q3","Q4")&"M"&SWITCH(MONTH(M1),2,"1",3,"2",4,"3",5,"1",6,"2",7,"3",8,"1",9,"2",10,"3",11,"2",12,"2",1,"3",)&"FY"&IF(MONTH(M1)=1,TEXT(M1,"yy"),TEXT(DATE(YEAR(M1)+1,MONTH(M1),DAY(M1)),"yy")) -> Q3M1FY25 | N2: =SWITCH(MONTH(N1),2,"Q1",3,"Q1",4,"Q1",5,"Q2",6,"Q2",7,"Q2",8,"Q3",9,"Q3",10,"Q3","Q4")&"M"&SWITCH(MONTH(N1),2,"1",3,"2",4,"3",5,"1",6,"2",7,"3",8,"1",9,"2",10,"3",11,"2",12,"2",1,"3",)&"FY"&IF(MONTH(N1)=1,TEXT(N1,"yy"),TEXT(DATE(YEAR(N1)+1,MONTH(N1),DAY(N1)),"yy")) -> Q3M2FY25 | ... AD2: =SWITCH(MONTH(AD1),2,"Q1",3,"Q1",4,"Q1",5,"Q2",6,"Q2",7,"Q2",8,"Q3",9,"Q3",10,"Q3","Q4")&"M"&SWITCH(MONTH(AD1),2,"1",3,"2",4,"3",5,"1",6,"2",7,"3",8,"1",9,"2",10,"3",11,"2",12,"2",1,"3",)&"FY"&IF(MONTH(AD1)=1,TEXT(AD1,"yy"),TEXT(DATE(YEAR(AD1)+1,MONTH(AD1),DAY(AD1)),"yy")) -> Q4M3FY26
B4: Ramping Rep Equivelents (RRE)
B5: OnlyCFO | C5: Account Executives - Enterprise | D5: 44562 | E5: 1/0/00 | G5: {=if(AND($E5<G$1,$E5<>0),0,iferror(INDEX(Drivers!$C$11:$N$13,MATCH($C5,Drivers!$B$11:$B$13,0),MATCH(min(((year(G$1)-YEAR($D5))*12+MONTH(G$1)-MONTH($D5)),12),Drivers!$C$10:$N$10))))} -> 1 | H5: {=if(AND($E5<H$1,$E5<>0),0,iferror(INDEX(Drivers!$C$11:$N$13,MATCH($C5,Drivers!$B$11:$B$13,0),MATCH(min(((year(H$1)-YEAR($D5))*12+MONTH(H$1)-MONTH($D5)),12),Drivers!$C$10:$N$10))))} -> 1 | I5: {=if(AND($E5<I$1,$E5<>0),0,iferror(INDEX(Drivers!$C$11:$N$13,MATCH($C5,Drivers!$B$11:$B$13,0),MATCH(min(((year(I$1)-YEAR($D5))*12+MONTH(I$1)-MONTH($D5)),12),Drivers!$C$10:$N$10))))} -> 1 | J5: {=if(AND($E5<J$1,$E5<>0),0,iferror(INDEX(Drivers!$C$11:$N$13,MATCH($C5,Drivers!$B$11:$B$13,0),MATCH(min(((year(J$1)-YEAR($D5))*12+MONTH(J$1)-MONTH($D5)),12),Drivers!$C$10:$N$10))))} -> 1 | K5: {=if(AND($E5<K$1,$E5<>0),0,iferror(INDEX(Drivers!$C$11:$N$13,MATCH($C5,Drivers!$B$11:$B$13,0),MATCH(min(((year(K$1)-YEAR($D5))*12+MONTH(K$1)-MONTH($D5)),12),Drivers!$C$10:$N$10))))} -> 1 | L5: {=if(AND($E5<L$1,$E5<>0),0,iferror(INDEX(Drivers!$C$11:$N$13,MATCH($C5,Drivers!$B$11:$B$13,0),MATCH(min(((year(L$1)-YEAR($D5))*12+MONTH(L$1)-MONTH($D5)),12),Drivers!$C$10:$N$10))))} -> 1 | M5: {=if(AND($E5<M$1,$E5<>0),0,iferror(INDEX(Drivers!$C$11:$N$13,MATCH($C5,Drivers!$B$11:$B$13,0),MATCH(min(((year(M$1)-YEAR($D5))*12+MONTH(M$1)-MONTH($D5)),12),Drivers!$C$10:$N$10))))} -> 1 | N5: {=if(AND($E5<N$1,$E5<>0),0,iferror(INDEX(Drivers!$C$11:$N$13,MATCH($C5,Drivers!$B$11:$B$13,0),MATCH(min(((year(N$1)-YEAR($D5))*12+MONTH(N$1)-MONTH($D5)),12),Drivers!$C$10:$N$10))))} -> 1 | ... AD5: {=if(AND($E5<AD$1,$E5<>0),0,iferror(INDEX(Drivers!$C$11:$N$13,MATCH($C5,Drivers!$B$11:$B$13,0),MATCH(min(((year(AD$1)-YEAR($D5))*12+MONTH(AD$1)-MONTH($D5)),12),Drivers!$C$10:$N$10))))} -> 1
B6: Bob | C6: Account Executives - Mid Market | D6: 44652 | E6: 1/0/00 | G6: {=if(AND($E6<G$1,$E6<>0),0,iferror(INDEX(Drivers!$C$11:$N$13,MATCH($C6,Drivers!$B$11:$B$13,0),MATCH(min(((year(G$1)-YEAR($D6))*12+MONTH(G$1)-MONTH($D6)),12),Drivers!$C$10:$N$10))))} -> 1 | H6: {=if(AND($E6<H$1,$E6<>0),0,iferror(INDEX(Drivers!$C$11:$N$13,MATCH($C6,Drivers!$B$11:$B$13,0),MATCH(min(((year(H$1)-YEAR($D6))*12+MONTH(H$1)-MONTH($D6)),12),Drivers!$C$10:$N$10))))} -> 1 | I6: {=if(AND($E6<I$1,$E6<>0),0,iferror(INDEX(Drivers!$C$11:$N$13,MATCH($C6,Drivers!$B$11:$B$13,0),MATCH(min(((year(I$1)-YEAR($D6))*12+MONTH(I$1)-MONTH($D6)),12),Drivers!$C$10:$N$10))))} -> 1 | J6: {=if(AND($E6<J$1,$E6<>0),0,iferror(INDEX(Drivers!$C$11:$N$13,MATCH($C6,Drivers!$B$11:$B$13,0),MATCH(min(((year(J$1)-YEAR($D6))*12+MONTH(J$1)-MONTH($D6)),12),Drivers!$C$10:$N$10))))} -> 1 | K6: {=if(AND($E6<K$1,$E6<>0),0,iferror(INDEX(Drivers!$C$11:$N$13,MATCH($C6,Drivers!$B$11:$B$13,0),MATCH(min(((year(K$1)-YEAR($D6))*12+MONTH(K$1)-MONTH($D6)),12),Drivers!$C$10:$N$10))))} -> 1 | L6: {=if(AND($E6<L$1,$E6<>0),0,iferror(INDEX(Drivers!$C$11:$N$13,MATCH($C6,Drivers!$B$11:$B$13,0),MATCH(min(((year(L$1)-YEAR($D6))*12+MONTH(L$1)-MONTH($D6)),12),Drivers!$C$10:$N$10))))} -> 1 | M6: {=if(AND($E6<M$1,$E6<>0),0,iferror(INDEX(Drivers!$C$11:$N$13,MATCH($C6,Drivers!$B$11:$B$13,0),MATCH(min(((year(M$1)-YEAR($D6))*12+MONTH(M$1)-MONTH($D6)),12),Drivers!$C$10:$N$10))))} -> 1 | N6: {=if(AND($E6<N$1,$E6<>0),0,iferror(INDEX(Drivers!$C$11:$N$13,MATCH($C6,Drivers!$B$11:$B$13,0),MATCH(min(((year(N$1)-YEAR($D6))*12+MONTH(N$1)-MONTH($D6)),12),Drivers!$C$10:$N$10))))} -> 1 | ... AD6: {=if(AND($E6<AD$1,$E6<>0),0,iferror(INDEX(Drivers!$C$11:$N$13,MATCH($C6,Drivers!$B$11:$B$13,0),MATCH(min(((year(AD$1)-YEAR($D6))*12+MONTH(AD$1)-MONTH($D6)),12),Drivers!$C$10:$N$10))))} -> 1
B7: John | C7: Account Executives - Enterprise | D7: 44835 | E7: 1/0/00 | G7: {=if(AND($E7<G$1,$E7<>0),0,iferror(INDEX(Drivers!$C$11:$N$13,MATCH($C7,Drivers!$B$11:$B$13,0),MATCH(min(((year(G$1)-YEAR($D7))*12+MONTH(G$1)-MONTH($D7)),12),Drivers!$C$10:$N$10))))} -> 1 | H7: {=if(AND($E7<H$1,$E7<>0),0,iferror(INDEX(Drivers!$C$11:$N$13,MATCH($C7,Drivers!$B$11:$B$13,0),MATCH(min(((year(H$1)-YEAR($D7))*12+MONTH(H$1)-MONTH($D7)),12),Drivers!$C$10:$N$10))))} -> 1 | I7: {=if(AND($E7<I$1,$E7<>0),0,iferror(INDEX(Drivers!$C$11:$N$13,MATCH($C7,Drivers!$B$11:$B$13,0),MATCH(min(((year(I$1)-YEAR($D7))*12+MONTH(I$1)-MONTH($D7)),12),Drivers!$C$10:$N$10))))} -> 1 | J7: {=if(AND($E7<J$1,$E7<>0),0,iferror(INDEX(Drivers!$C$11:$N$13,MATCH($C7,Drivers!$B$11:$B$13,0),MATCH(min(((year(J$1)-YEAR($D7))*12+MONTH(J$1)-MONTH($D7)),12),Drivers!$C$10:$N$10))))} -> 1 | K7: {=if(AND($E7<K$1,$E7<>0),0,iferror(INDEX(Drivers!$C$11:$N$13,MATCH($C7,Drivers!$B$11:$B$13,0),MATCH(min(((year(K$1)-YEAR($D7))*12+MONTH(K$1)-MONTH($D7)),12),Drivers!$C$10:$N$10))))} -> 1 | L7: {=if(AND($E7<L$1,$E7<>0),0,iferror(INDEX(Drivers!$C$11:$N$13,MATCH($C7,Drivers!$B$11:$B$13,0),MATCH(min(((year(L$1)-YEAR($D7))*12+MONTH(L$1)-MONTH($D7)),12),Drivers!$C$10:$N$10))))} -> 1 | M7: {=if(AND($E7<M$1,$E7<>0),0,iferror(INDEX(Drivers!$C$11:$N$13,MATCH($C7,Drivers!$B$11:$B$13,0),MATCH(min(((year(M$1)-YEAR($D7))*12+MONTH(M$1)-MONTH($D7)),12),Drivers!$C$10:$N$10))))} -> 1 | N7: {=if(AND($E7<N$1,$E7<>0),0,iferror(INDEX(Drivers!$C$11:$N$13,MATCH($C7,Drivers!$B$11:$B$13,0),MATCH(min(((year(N$1)-YEAR($D7))*12+MONTH(N$1)-MONTH($D7)),12),Drivers!$C$10:$N$10))))} -> 1 | ... AD7: {=if(AND($E7<AD$1,$E7<>0),0,iferror(INDEX(Drivers!$C$11:$N$13,MATCH($C7,Drivers!$B$11:$B$13,0),MATCH(min(((year(AD$1)-YEAR($D7))*12+MONTH(AD$1)-MONTH($D7)),12),Drivers!$C$10:$N$10))))} -> 1
B8: CJ | C8: Account Executives - Enterprise | D8: 44986 | E8: 45323 | G8: {=if(AND($E8<G$1,$E8<>0),0,iferror(INDEX(Drivers!$C$11:$N$13,MATCH($C8,Drivers!$B$11:$B$13,0),MATCH(min(((year(G$1)-YEAR($D8))*12+MONTH(G$1)-MONTH($D8)),12),Drivers!$C$10:$N$10))))} -> 0 | H8: {=if(AND($E8<H$1,$E8<>0),0,iferror(INDEX(Drivers!$C$11:$N$13,MATCH($C8,Drivers!$B$11:$B$13,0),MATCH(min(((year(H$1)-YEAR($D8))*12+MONTH(H$1)-MONTH($D8)),12),Drivers!$C$10:$N$10))))} -> 0 | I8: {=if(AND($E8<I$1,$E8<>0),0,iferror(INDEX(Drivers!$C$11:$N$13,MATCH($C8,Drivers!$B$11:$B$13,0),MATCH(min(((year(I$1)-YEAR($D8))*12+MONTH(I$1)-MONTH($D8)),12),Drivers!$C$10:$N$10))))} -> 0 | J8: {=if(AND($E8<J$1,$E8<>0),0,iferror(INDEX(Drivers!$C$11:$N$13,MATCH($C8,Drivers!$B$11:$B$13,0),MATCH(min(((year(J$1)-YEAR($D8))*12+MONTH(J$1)-MONTH($D8)),12),Drivers!$C$10:$N$10))))} -> 0 | K8: {=if(AND($E8<K$1,$E8<>0),0,iferror(INDEX(Drivers!$C$11:$N$13,MATCH($C8,Drivers!$B$11:$B$13,0),MATCH(min(((year(K$1)-YEAR($D8))*12+MONTH(K$1)-MONTH($D8)),12),Drivers!$C$10:$N$10))))} -> 0 | L8: {=if(AND($E8<L$1,$E8<>0),0,iferror(INDEX(Drivers!$C$11:$N$13,MATCH($C8,Drivers!$B$11:$B$13,0),MATCH(min(((year(L$1)-YEAR($D8))*12+MONTH(L$1)-MONTH($D8)),12),Drivers!$C$10:$N$10))))} -> 0 | M8: {=if(AND($E8<M$1,$E8<>0),0,iferror(INDEX(Drivers!$C$11:$N$13,MATCH($C8,Drivers!$B$11:$B$13,0),MATCH(min(((year(M$1)-YEAR($D8))*12+MONTH(M$1)-MONTH($D8)),12),Drivers!$C$10:$N$10))))} -> 0 | N8: {=if(AND($E8<N$1,$E8<>0),0,iferror(INDEX(Drivers!$C$11:$N$13,MATCH($C8,Drivers!$B$11:$B$13,0),MATCH(min(((year(N$1)-YEAR($D8))*12+MONTH(N$1)-MONTH($D8)),12),Drivers!$C$10:$N$10))))} -> 0 | ... AD8: {=if(AND($E8<AD$1,$E8<>0),0,iferror(INDEX(Drivers!$C$11:$N$13,MATCH($C8,Drivers!$B$11:$B$13,0),MATCH(min(((year(AD$1)-YEAR($D8))*12+MONTH(AD$1)-MONTH($D8)),12),Drivers!$C$10:$N$10))))} -> 0
B9: SecretCFO | C9: Account Executives - Mid Market | D9: 44713 | E9: 1/0/00 | G9: {=if(AND($E9<G$1,$E9<>0),0,iferror(INDEX(Drivers!$C$11:$N$13,MATCH($C9,Drivers!$B$11:$B$13,0),MATCH(min(((year(G$1)-YEAR($D9))*12+MONTH(G$1)-MONTH($D9)),12),Drivers!$C$10:$N$10))))} -> 1 | H9: {=if(AND($E9<H$1,$E9<>0),0,iferror(INDEX(Drivers!$C$11:$N$13,MATCH($C9,Drivers!$B$11:$B$13,0),MATCH(min(((year(H$1)-YEAR($D9))*12+MONTH(H$1)-MONTH($D9)),12),Drivers!$C$10:$N$10))))} -> 1 | I9: {=if(AND($E9<I$1,$E9<>0),0,iferror(INDEX(Drivers!$C$11:$N$13,MATCH($C9,Drivers!$B$11:$B$13,0),MATCH(min(((year(I$1)-YEAR($D9))*12+MONTH(I$1)-MONTH($D9)),12),Drivers!$C$10:$N$10))))} -> 1 | J9: {=if(AND($E9<J$1,$E9<>0),0,iferror(INDEX(Drivers!$C$11:$N$13,MATCH($C9,Drivers!$B$11:$B$13,0),MATCH(min(((year(J$1)-YEAR($D9))*12+MONTH(J$1)-MONTH($D9)),12),Drivers!$C$10:$N$10))))} -> 1 | K9: {=if(AND($E9<K$1,$E9<>0),0,iferror(INDEX(Drivers!$C$11:$N$13,MATCH($C9,Drivers!$B$11:$B$13,0),MATCH(min(((year(K$1)-YEAR($D9))*12+MONTH(K$1)-MONTH($D9)),12),Drivers!$C$10:$N$10))))} -> 1 | L9: {=if(AND($E9<L$1,$E9<>0),0,iferror(INDEX(Drivers!$C$11:$N$13,MATCH($C9,Drivers!$B$11:$B$13,0),MATCH(min(((year(L$1)-YEAR($D9))*12+MONTH(L$1)-MONTH($D9)),12),Drivers!$C$10:$N$10))))} -> 1 | M9: {=if(AND($E9<M$1,$E9<>0),0,iferror(INDEX(Drivers!$C$11:$N$13,MATCH($C9,Drivers!$B$11:$B$13,0),MATCH(min(((year(M$1)-YEAR($D9))*12+MONTH(M$1)-MONTH($D9)),12),Drivers!$C$10:$N$10))))} -> 1 | N9: {=if(AND($E9<N$1,$E9<>0),0,iferror(INDEX(Drivers!$C$11:$N$13,MATCH($C9,Drivers!$B$11:$B$13,0),MATCH(min(((year(N$1)-YEAR($D9))*12+MONTH(N$1)-MONTH($D9)),12),Drivers!$C$10:$N$10))))} -> 1 | ... AD9: {=if(AND($E9<AD$1,$E9<>0),0,iferror(INDEX(Drivers!$C$11:$N$13,MATCH($C9,Drivers!$B$11:$B$13,0),MATCH(min(((year(AD$1)-YEAR($D9))*12+MONTH(AD$1)-MONTH($D9)),12),Drivers!$C$10:$N$10))))} -> 1
B10: Dory | C10: Account Executives - Mid Market | D10: 44470 | E10: 45444 | G10: {=if(AND($E10<G$1,$E10<>0),0,iferror(INDEX(Drivers!$C$11:$N$13,MATCH($C10,Drivers!$B$11:$B$13,0),MATCH(min(((year(G$1)-YEAR($D10))*12+MONTH(G$1)-MONTH($D10)),12),Drivers!$C$10:$N$10))))} -> 1 | H10: {=if(AND($E10<H$1,$E10<>0),0,iferror(INDEX(Drivers!$C$11:$N$13,MATCH($C10,Drivers!$B$11:$B$13,0),MATCH(min(((year(H$1)-YEAR($D10))*12+MONTH(H$1)-MONTH($D10)),12),Drivers!$C$10:$N$10))))} -> 1 | I10: {=if(AND($E10<I$1,$E10<>0),0,iferror(INDEX(Drivers!$C$11:$N$13,MATCH($C10,Drivers!$B$11:$B$13,0),MATCH(min(((year(I$1)-YEAR($D10))*12+MONTH(I$1)-MONTH($D10)),12),Drivers!$C$10:$N$10))))} -> 1 | J10: {=if(AND($E10<J$1,$E10<>0),0,iferror(INDEX(Drivers!$C$11:$N$13,MATCH($C10,Drivers!$B$11:$B$13,0),MATCH(min(((year(J$1)-YEAR($D10))*12+MONTH(J$1)-MONTH($D10)),12),Drivers!$C$10:$N$10))))} -> 1 | K10: {=if(AND($E10<K$1,$E10<>0),0,iferror(INDEX(Drivers!$C$11:$N$13,MATCH($C10,Drivers!$B$11:$B$13,0),MATCH(min(((year(K$1)-YEAR($D10))*12+MONTH(K$1)-MONTH($D10)),12),Drivers!$C$10:$N$10))))} -> 0 | L10: {=if(AND($E10<L$1,$E10<>0),0,iferror(INDEX(Drivers!$C$11:$N$13,MATCH($C10,Drivers!$B$11:$B$13,0),MATCH(min(((year(L$1)-YEAR($D10))*12+MONTH(L$1)-MONTH($D10)),12),Drivers!$C$10:$N$10))))} -> 0 | M10: {=if(AND($E10<M$1,$E10<>0),0,iferror(INDEX(Drivers!$C$11:$N$13,MATCH($C10,Drivers!$B$11:$B$13,0),MATCH(min(((year(M$1)-YEAR($D10))*12+MONTH(M$1)-MONTH($D10)),12),Drivers!$C$10:$N$10))))} -> 0 | N10: {=if(AND($E10<N$1,$E10<>0),0,iferror(INDEX(Drivers!$C$11:$N$13,MATCH($C10,Drivers!$B$11:$B$13,0),MATCH(min(((year(N$1)-YEAR($D10))*12+MONTH(N$1)-MONTH($D10)),12),Drivers!$C$10:$N$10))))} -> 0 | ... AD10: {=if(AND($E10<AD$1,$E10<>0),0,iferror(INDEX(Drivers!$C$11:$N$13,MATCH($C10,Drivers!$B$11:$B$13,0),MATCH(min(((year(AD$1)-YEAR($D10))*12+MONTH(AD$1)-MONTH($D10)),12),Drivers!$C$10:$N$10))))} -> 0
B11: Brittany | C11: Account Executives - Mid Market | D11: 45261 | E11: 1/0/00 | G11: {=if(AND($E11<G$1,$E11<>0),0,iferror(INDEX(Drivers!$C$11:$N$13,MATCH($C11,Drivers!$B$11:$B$13,0),MATCH(min(((year(G$1)-YEAR($D11))*12+MONTH(G$1)-MONTH($D11)),12),Drivers!$C$10:$N$10))))} -> 0 | H11: {=if(AND($E11<H$1,$E11<>0),0,iferror(INDEX(Drivers!$C$11:$N$13,MATCH($C11,Drivers!$B$11:$B$13,0),MATCH(min(((year(H$1)-YEAR($D11))*12+MONTH(H$1)-MONTH($D11)),12),Drivers!$C$10:$N$10))))} -> 0.25 | I11: {=if(AND($E11<I$1,$E11<>0),0,iferror(INDEX(Drivers!$C$11:$N$13,MATCH($C11,Drivers!$B$11:$B$13,0),MATCH(min(((year(I$1)-YEAR($D11))*12+MONTH(I$1)-MONTH($D11)),12),Drivers!$C$10:$N$10))))} -> 0.5 | J11: {=if(AND($E11<J$1,$E11<>0),0,iferror(INDEX(Drivers!$C$11:$N$13,MATCH($C11,Drivers!$B$11:$B$13,0),MATCH(min(((year(J$1)-YEAR($D11))*12+MONTH(J$1)-MONTH($D11)),12),Drivers!$C$10:$N$10))))} -> 0.75 | K11: {=if(AND($E11<K$1,$E11<>0),0,iferror(INDEX(Drivers!$C$11:$N$13,MATCH($C11,Drivers!$B$11:$B$13,0),MATCH(min(((year(K$1)-YEAR($D11))*12+MONTH(K$1)-MONTH($D11)),12),Drivers!$C$10:$N$10))))} -> 1 | L11: {=if(AND($E11<L$1,$E11<>0),0,iferror(INDEX(Drivers!$C$11:$N$13,MATCH($C11,Drivers!$B$11:$B$13,0),MATCH(min(((year(L$1)-YEAR($D11))*12+MONTH(L$1)-MONTH($D11)),12),Drivers!$C$10:$N$10))))} -> 1 | M11: {=if(AND($E11<M$1,$E11<>0),0,iferror(INDEX(Drivers!$C$11:$N$13,MATCH($C11,Drivers!$B$11:$B$13,0),MATCH(min(((year(M$1)-YEAR($D11))*12+MONTH(M$1)-MONTH($D11)),12),Drivers!$C$10:$N$10))))} -> 1 | N11: {=if(AND($E11<N$1,$E11<>0),0,iferror(INDEX(Drivers!$C$11:$N$13,MATCH($C11,Drivers!$B$11:$B$13,0),MATCH(min(((year(N$1)-YEAR($D11))*12+MONTH(N$1)-MONTH($D11)),12),Drivers!$C$10:$N$10))))} -> 1 | ... AD11: {=if(AND($E11<AD$1,$E11<>0),0,iferror(INDEX(Drivers!$C$11:$N$13,MATCH($C11,Drivers!$B$11:$B$13,0),MATCH(min(((year(AD$1)-YEAR($D11))*12+MONTH(AD$1)-MONTH($D11)),12),Drivers!$C$10:$N$10))))} -> 1
B12: Dora the Explorer | C12: Account Executives - Enterprise | D12: 45321 | E12: 1/0/00 | G12: {=if(AND($E12<G$1,$E12<>0),0,iferror(INDEX(Drivers!$C$11:$N$13,MATCH($C12,Drivers!$B$11:$B$13,0),MATCH(min(((year(G$1)-YEAR($D12))*12+MONTH(G$1)-MONTH($D12)),12),Drivers!$C$10:$N$10))))} -> 0 | H12: {=if(AND($E12<H$1,$E12<>0),0,iferror(INDEX(Drivers!$C$11:$N$13,MATCH($C12,Drivers!$B$11:$B$13,0),MATCH(min(((year(H$1)-YEAR($D12))*12+MONTH(H$1)-MONTH($D12)),12),Drivers!$C$10:$N$10))))} -> 0 | I12: {=if(AND($E12<I$1,$E12<>0),0,iferror(INDEX(Drivers!$C$11:$N$13,MATCH($C12,Drivers!$B$11:$B$13,0),MATCH(min(((year(I$1)-YEAR($D12))*12+MONTH(I$1)-MONTH($D12)),12),Drivers!$C$10:$N$10))))} -> 0 | J12: {=if(AND($E12<J$1,$E12<>0),0,iferror(INDEX(Drivers!$C$11:$N$13,MATCH($C12,Drivers!$B$11:$B$13,0),MATCH(min(((year(J$1)-YEAR($D12))*12+MONTH(J$1)-MONTH($D12)),12),Drivers!$C$10:$N$10))))} -> 0.25 | K12: {=if(AND($E12<K$1,$E12<>0),0,iferror(INDEX(Drivers!$C$11:$N$13,MATCH($C12,Drivers!$B$11:$B$13,0),MATCH(min(((year(K$1)-YEAR($D12))*12+MONTH(K$1)-MONTH($D12)),12),Drivers!$C$10:$N$10))))} -> 0.5 | L12: {=if(AND($E12<L$1,$E12<>0),0,iferror(INDEX(Drivers!$C$11:$N$13,MATCH($C12,Drivers!$B$11:$B$13,0),MATCH(min(((year(L$1)-YEAR($D12))*12+MONTH(L$1)-MONTH($D12)),12),Drivers!$C$10:$N$10))))} -> 0.5 | M12: {=if(AND($E12<M$1,$E12<>0),0,iferror(INDEX(Drivers!$C$11:$N$13,MATCH($C12,Drivers!$B$11:$B$13,0),MATCH(min(((year(M$1)-YEAR($D12))*12+MONTH(M$1)-MONTH($D12)),12),Drivers!$C$10:$N$10))))} -> 0.75 | N12: {=if(AND($E12<N$1,$E12<>0),0,iferror(INDEX(Drivers!$C$11:$N$13,MATCH($C12,Drivers!$B$11:$B$13,0),MATCH(min(((year(N$1)-YEAR($D12))*12+MONTH(N$1)-MONTH($D12)),12),Drivers!$C$10:$N$10))))} -> 0.75 | ... AD12: {=if(AND($E12<AD$1,$E12<>0),0,iferror(INDEX(Drivers!$C$11:$N$13,MATCH($C12,Drivers!$B$11:$B$13,0),MATCH(min(((year(AD$1)-YEAR($D12))*12+MONTH(AD$1)-MONTH($D12)),12),Drivers!$C$10:$N$10))))} -> 1
B13: Elsa | C13: Account Executives - Mid Market | D13: 45078 | E13: 1/0/00 | G13: {=if(AND($E13<G$1,$E13<>0),0,iferror(INDEX(Drivers!$C$11:$N$13,MATCH($C13,Drivers!$B$11:$B$13,0),MATCH(min(((year(G$1)-YEAR($D13))*12+MONTH(G$1)-MONTH($D13)),12),Drivers!$C$10:$N$10))))} -> 1 | H13: {=if(AND($E13<H$1,$E13<>0),0,iferror(INDEX(Drivers!$C$11:$N$13,MATCH($C13,Drivers!$B$11:$B$13,0),MATCH(min(((year(H$1)-YEAR($D13))*12+MONTH(H$1)-MONTH($D13)),12),Drivers!$C$10:$N$10))))} -> 1 | I13: {=if(AND($E13<I$1,$E13<>0),0,iferror(INDEX(Drivers!$C$11:$N$13,MATCH($C13,Drivers!$B$11:$B$13,0),MATCH(min(((year(I$1)-YEAR($D13))*12+MONTH(I$1)-MONTH($D13)),12),Drivers!$C$10:$N$10))))} -> 1 | J13: {=if(AND($E13<J$1,$E13<>0),0,iferror(INDEX(Drivers!$C$11:$N$13,MATCH($C13,Drivers!$B$11:$B$13,0),MATCH(min(((year(J$1)-YEAR($D13))*12+MONTH(J$1)-MONTH($D13)),12),Drivers!$C$10:$N$10))))} -> 1 | K13: {=if(AND($E13<K$1,$E13<>0),0,iferror(INDEX(Drivers!$C$11:$N$13,MATCH($C13,Drivers!$B$11:$B$13,0),MATCH(min(((year(K$1)-YEAR($D13))*12+MONTH(K$1)-MONTH($D13)),12),Drivers!$C$10:$N$10))))} -> 1 | L13: {=if(AND($E13<L$1,$E13<>0),0,iferror(INDEX(Drivers!$C$11:$N$13,MATCH($C13,Drivers!$B$11:$B$13,0),MATCH(min(((year(L$1)-YEAR($D13))*12+MONTH(L$1)-MONTH($D13)),12),Drivers!$C$10:$N$10))))} -> 1 | M13: {=if(AND($E13<M$1,$E13<>0),0,iferror(INDEX(Drivers!$C$11:$N$13,MATCH($C13,Drivers!$B$11:$B$13,0),MATCH(min(((year(M$1)-YEAR($D13))*12+MONTH(M$1)-MONTH($D13)),12),Drivers!$C$10:$N$10))))} -> 1 | N13: {=if(AND($E13<N$1,$E13<>0),0,iferror(INDEX(Drivers!$C$11:$N$13,MATCH($C13,Drivers!$B$11:$B$13,0),MATCH(min(((year(N$1)-YEAR($D13))*12+MONTH(N$1)-MONTH($D13)),12),Drivers!$C$10:$N$10))))} -> 1 | ... AD13: {=if(AND($E13<AD$1,$E13<>0),0,iferror(INDEX(Drivers!$C$11:$N$13,MATCH($C13,Drivers!$B$11:$B$13,0),MATCH(min(((year(AD$1)-YEAR($D13))*12+MONTH(AD$1)-MONTH($D13)),12),Drivers!$C$10:$N$10))))} -> 1
B14: Snow White | C14: Account Executives - Enterprise | D14: 45200 | E14: 1/0/00 | G14: {=if(AND($E14<G$1,$E14<>0),0,iferror(INDEX(Drivers!$C$11:$N$13,MATCH($C14,Drivers!$B$11:$B$13,0),MATCH(min(((year(G$1)-YEAR($D14))*12+MONTH(G$1)-MONTH($D14)),12),Drivers!$C$10:$N$10))))} -> 0.25 | H14: {=if(AND($E14<H$1,$E14<>0),0,iferror(INDEX(Drivers!$C$11:$N$13,MATCH($C14,Drivers!$B$11:$B$13,0),MATCH(min(((year(H$1)-YEAR($D14))*12+MONTH(H$1)-MONTH($D14)),12),Drivers!$C$10:$N$10))))} -> 0.5 | I14: {=if(AND($E14<I$1,$E14<>0),0,iferror(INDEX(Drivers!$C$11:$N$13,MATCH($C14,Drivers!$B$11:$B$13,0),MATCH(min(((year(I$1)-YEAR($D14))*12+MONTH(I$1)-MONTH($D14)),12),Drivers!$C$10:$N$10))))} -> 0.5 | J14: {=if(AND($E14<J$1,$E14<>0),0,iferror(INDEX(Drivers!$C$11:$N$13,MATCH($C14,Drivers!$B$11:$B$13,0),MATCH(min(((year(J$1)-YEAR($D14))*12+MONTH(J$1)-MONTH($D14)),12),Drivers!$C$10:$N$10))))} -> 0.75 | K14: {=if(AND($E14<K$1,$E14<>0),0,iferror(INDEX(Drivers!$C$11:$N$13,MATCH($C14,Drivers!$B$11:$B$13,0),MATCH(min(((year(K$1)-YEAR($D14))*12+MONTH(K$1)-MONTH($D14)),12),Drivers!$C$10:$N$10))))} -> 0.75 | L14: {=if(AND($E14<L$1,$E14<>0),0,iferror(INDEX(Drivers!$C$11:$N$13,MATCH($C14,Drivers!$B$11:$B$13,0),MATCH(min(((year(L$1)-YEAR($D14))*12+MONTH(L$1)-MONTH($D14)),12),Drivers!$C$10:$N$10))))} -> 1 | M14: {=if(AND($E14<M$1,$E14<>0),0,iferror(INDEX(Drivers!$C$11:$N$13,MATCH($C14,Drivers!$B$11:$B$13,0),MATCH(min(((year(M$1)-YEAR($D14))*12+MONTH(M$1)-MONTH($D14)),12),Drivers!$C$10:$N$10))))} -> 1 | N14: {=if(AND($E14<N$1,$E14<>0),0,iferror(INDEX(Drivers!$C$11:$N$13,MATCH($C14,Drivers!$B$11:$B$13,0),MATCH(min(((year(N$1)-YEAR($D14))*12+MONTH(N$1)-MONTH($D14)),12),Drivers!$C$10:$N$10))))} -> 1 | ... AD14: {=if(AND($E14<AD$1,$E14<>0),0,iferror(INDEX(Drivers!$C$11:$N$13,MATCH($C14,Drivers!$B$11:$B$13,0),MATCH(min(((year(AD$1)-YEAR($D14))*12+MONTH(AD$1)-MONTH($D14)),12),Drivers!$C$10:$N$10))))} -> 1
C15: Account Executives - Mid Market | D15: 45261 | E15: 1/0/00 | G15: {=if(AND($E15<G$1,$E15<>0),0,iferror(INDEX(Drivers!$C$11:$N$13,MATCH($C15,Drivers!$B$11:$B$13,0),MATCH(min(((year(G$1)-YEAR($D15))*12+MONTH(G$1)-MONTH($D15)),12),Drivers!$C$10:$N$10))))} -> 0 | H15: {=if(AND($E15<H$1,$E15<>0),0,iferror(INDEX(Drivers!$C$11:$N$13,MATCH($C15,Drivers!$B$11:$B$13,0),MATCH(min(((year(H$1)-YEAR($D15))*12+MONTH(H$1)-MONTH($D15)),12),Drivers!$C$10:$N$10))))} -> 0.25 | I15: {=if(AND($E15<I$1,$E15<>0),0,iferror(INDEX(Drivers!$C$11:$N$13,MATCH($C15,Drivers!$B$11:$B$13,0),MATCH(min(((year(I$1)-YEAR($D15))*12+MONTH(I$1)-MONTH($D15)),12),Drivers!$C$10:$N$10))))} -> 0.5 | J15: {=if(AND($E15<J$1,$E15<>0),0,iferror(INDEX(Drivers!$C$11:$N$13,MATCH($C15,Drivers!$B$11:$B$13,0),MATCH(min(((year(J$1)-YEAR($D15))*12+MONTH(J$1)-MONTH($D15)),12),Drivers!$C$10:$N$10))))} -> 0.75 | K15: {=if(AND($E15<K$1,$E15<>0),0,iferror(INDEX(Drivers!$C$11:$N$13,MATCH($C15,Drivers!$B$11:$B$13,0),MATCH(min(((year(K$1)-YEAR($D15))*12+MONTH(K$1)-MONTH($D15)),12),Drivers!$C$10:$N$10))))} -> 1 | L15: {=if(AND($E15<L$1,$E15<>0),0,iferror(INDEX(Drivers!$C$11:$N$13,MATCH($C15,Drivers!$B$11:$B$13,0),MATCH(min(((year(L$1)-YEAR($D15))*12+MONTH(L$1)-MONTH($D15)),12),Drivers!$C$10:$N$10))))} -> 1 | M15: {=if(AND($E15<M$1,$E15<>0),0,iferror(INDEX(Drivers!$C$11:$N$13,MATCH($C15,Drivers!$B$11:$B$13,0),MATCH(min(((year(M$1)-YEAR($D15))*12+MONTH(M$1)-MONTH($D15)),12),Drivers!$C$10:$N$10))))} -> 1 | N15: {=if(AND($E15<N$1,$E15<>0),0,iferror(INDEX(Drivers!$C$11:$N$13,MATCH($C15,Drivers!$B$11:$B$13,0),MATCH(min(((year(N$1)-YEAR($D15))*12+MONTH(N$1)-MONTH($D15)),12),Drivers!$C$10:$N$10))))} -> 1 | ... AD15: {=if(AND($E15<AD$1,$E15<>0),0,iferror(INDEX(Drivers!$C$11:$N$13,MATCH($C15,Drivers!$B$11:$B$13,0),MATCH(min(((year(AD$1)-YEAR($D15))*12+MONTH(AD$1)-MONTH($D15)),12),Drivers!$C$10:$N$10))))} -> 1
C16: Account Executives - Mid Market | D16: 45321 | E16: 1/0/00 | G16: {=if(AND($E16<G$1,$E16<>0),0,iferror(INDEX(Drivers!$C$11:$N$13,MATCH($C16,Drivers!$B$11:$B$13,0),MATCH(min(((year(G$1)-YEAR($D16))*12+MONTH(G$1)-MONTH($D16)),12),Drivers!$C$10:$N$10))))} -> 0 | H16: {=if(AND($E16<H$1,$E16<>0),0,iferror(INDEX(Drivers!$C$11:$N$13,MATCH($C16,Drivers!$B$11:$B$13,0),MATCH(min(((year(H$1)-YEAR($D16))*12+MONTH(H$1)-MONTH($D16)),12),Drivers!$C$10:$N$10))))} -> 0 | I16: {=if(AND($E16<I$1,$E16<>0),0,iferror(INDEX(Drivers!$C$11:$N$13,MATCH($C16,Drivers!$B$11:$B$13,0),MATCH(min(((year(I$1)-YEAR($D16))*12+MONTH(I$1)-MONTH($D16)),12),Drivers!$C$10:$N$10))))} -> 0.25 | J16: {=if(AND($E16<J$1,$E16<>0),0,iferror(INDEX(Drivers!$C$11:$N$13,MATCH($C16,Drivers!$B$11:$B$13,0),MATCH(min(((year(J$1)-YEAR($D16))*12+MONTH(J$1)-MONTH($D16)),12),Drivers!$C$10:$N$10))))} -> 0.5 | K16: {=if(AND($E16<K$1,$E16<>0),0,iferror(INDEX(Drivers!$C$11:$N$13,MATCH($C16,Drivers!$B$11:$B$13,0),MATCH(min(((year(K$1)-YEAR($D16))*12+MONTH(K$1)-MONTH($D16)),12),Drivers!$C$10:$N$10))))} -> 0.75 | L16: {=if(AND($E16<L$1,$E16<>0),0,iferror(INDEX(Drivers!$C$11:$N$13,MATCH($C16,Drivers!$B$11:$B$13,0),MATCH(min(((year(L$1)-YEAR($D16))*12+MONTH(L$1)-MONTH($D16)),12),Drivers!$C$10:$N$10))))} -> 1 | M16: {=if(AND($E16<M$1,$E16<>0),0,iferror(INDEX(Drivers!$C$11:$N$13,MATCH($C16,Drivers!$B$11:$B$13,0),MATCH(min(((year(M$1)-YEAR($D16))*12+MONTH(M$1)-MONTH($D16)),12),Drivers!$C$10:$N$10))))} -> 1 | N16: {=if(AND($E16<N$1,$E16<>0),0,iferror(INDEX(Drivers!$C$11:$N$13,MATCH($C16,Drivers!$B$11:$B$13,0),MATCH(min(((year(N$1)-YEAR($D16))*12+MONTH(N$1)-MONTH($D16)),12),Drivers!$C$10:$N$10))))} -> 1 | ... AD16: {=if(AND($E16<AD$1,$E16<>0),0,iferror(INDEX(Drivers!$C$11:$N$13,MATCH($C16,Drivers!$B$11:$B$13,0),MATCH(min(((year(AD$1)-YEAR($D16))*12+MONTH(AD$1)-MONTH($D16)),12),Drivers!$C$10:$N$10))))} -> 1
C17: Account Executives - SMB | D17: 45337 | E17: 1/0/00 | G17: {=if(AND($E17<G$1,$E17<>0),0,iferror(INDEX(Drivers!$C$11:$N$13,MATCH($C17,Drivers!$B$11:$B$13,0),MATCH(min(((year(G$1)-YEAR($D17))*12+MONTH(G$1)-MONTH($D17)),12),Drivers!$C$10:$N$10))))} | H17: {=if(AND($E17<H$1,$E17<>0),0,iferror(INDEX(Drivers!$C$11:$N$13,MATCH($C17,Drivers!$B$11:$B$13,0),MATCH(min(((year(H$1)-YEAR($D17))*12+MONTH(H$1)-MONTH($D17)),12),Drivers!$C$10:$N$10))))} -> 0 | I17: {=if(AND($E17<I$1,$E17<>0),0,iferror(INDEX(Drivers!$C$11:$N$13,MATCH($C17,Drivers!$B$11:$B$13,0),MATCH(min(((year(I$1)-YEAR($D17))*12+MONTH(I$1)-MONTH($D17)),12),Drivers!$C$10:$N$10))))} -> 0 | J17: {=if(AND($E17<J$1,$E17<>0),0,iferror(INDEX(Drivers!$C$11:$N$13,MATCH($C17,Drivers!$B$11:$B$13,0),MATCH(min(((year(J$1)-YEAR($D17))*12+MONTH(J$1)-MONTH($D17)),12),Drivers!$C$10:$N$10))))} -> 0.5 | K17: {=if(AND($E17<K$1,$E17<>0),0,iferror(INDEX(Drivers!$C$11:$N$13,MATCH($C17,Drivers!$B$11:$B$13,0),MATCH(min(((year(K$1)-YEAR($D17))*12+MONTH(K$1)-MONTH($D17)),12),Drivers!$C$10:$N$10))))} -> 0.75 | L17: {=if(AND($E17<L$1,$E17<>0),0,iferror(INDEX(Drivers!$C$11:$N$13,MATCH($C17,Drivers!$B$11:$B$13,0),MATCH(min(((year(L$1)-YEAR($D17))*12+MONTH(L$1)-MONTH($D17)),12),Drivers!$C$10:$N$10))))} -> 1 | M17: {=if(AND($E17<M$1,$E17<>0),0,iferror(INDEX(Drivers!$C$11:$N$13,MATCH($C17,Drivers!$B$11:$B$13,0),MATCH(min(((year(M$1)-YEAR($D17))*12+MONTH(M$1)-MONTH($D17)),12),Drivers!$C$10:$N$10))))} -> 1 | N17: {=if(AND($E17<N$1,$E17<>0),0,iferror(INDEX(Drivers!$C$11:$N$13,MATCH($C17,Drivers!$B$11:$B$13,0),MATCH(min(((year(N$1)-YEAR($D17))*12+MONTH(N$1)-MONTH($D17)),12),Drivers!$C$10:$N$10))))} -> 1 | ... AD17: {=if(AND($E17<AD$1,$E17<>0),0,iferror(INDEX(Drivers!$C$11:$N$13,MATCH($C17,Drivers!$B$11:$B$13,0),MATCH(min(((year(AD$1)-YEAR($D17))*12+MONTH(AD$1)-MONTH($D17)),12),Drivers!$C$10:$N$10))))} -> 1
C18: Account Executives - SMB | D18: 45597 | E18: 1/0/00 | G18: {=if(AND($E18<G$1,$E18<>0),0,iferror(INDEX(Drivers!$C$11:$N$13,MATCH($C18,Drivers!$B$11:$B$13,0),MATCH(min(((year(G$1)-YEAR($D18))*12+MONTH(G$1)-MONTH($D18)),12),Drivers!$C$10:$N$10))))} | H18: {=if(AND($E18<H$1,$E18<>0),0,iferror(INDEX(Drivers!$C$11:$N$13,MATCH($C18,Drivers!$B$11:$B$13,0),MATCH(min(((year(H$1)-YEAR($D18))*12+MONTH(H$1)-MONTH($D18)),12),Drivers!$C$10:$N$10))))} | I18: {=if(AND($E18<I$1,$E18<>0),0,iferror(INDEX(Drivers!$C$11:$N$13,MATCH($C18,Drivers!$B$11:$B$13,0),MATCH(min(((year(I$1)-YEAR($D18))*12+MONTH(I$1)-MONTH($D18)),12),Drivers!$C$10:$N$10))))} | J18: {=if(AND($E18<J$1,$E18<>0),0,iferror(INDEX(Drivers!$C$11:$N$13,MATCH($C18,Drivers!$B$11:$B$13,0),MATCH(min(((year(J$1)-YEAR($D18))*12+MONTH(J$1)-MONTH($D18)),12),Drivers!$C$10:$N$10))))} | K18: {=if(AND($E18<K$1,$E18<>0),0,iferror(INDEX(Drivers!$C$11:$N$13,MATCH($C18,Drivers!$B$11:$B$13,0),MATCH(min(((year(K$1)-YEAR($D18))*12+MONTH(K$1)-MONTH($D18)),12),Drivers!$C$10:$N$10))))} | L18: {=if(AND($E18<L$1,$E18<>0),0,iferror(INDEX(Drivers!$C$11:$N$13,MATCH($C18,Drivers!$B$11:$B$13,0),MATCH(min(((year(L$1)-YEAR($D18))*12+MONTH(L$1)-MONTH($D18)),12),Drivers!$C$10:$N$10))))} | M18: {=if(AND($E18<M$1,$E18<>0),0,iferror(INDEX(Drivers!$C$11:$N$13,MATCH($C18,Drivers!$B$11:$B$13,0),MATCH(min(((year(M$1)-YEAR($D18))*12+MONTH(M$1)-MONTH($D18)),12),Drivers!$C$10:$N$10))))} | N18: {=if(AND($E18<N$1,$E18<>0),0,iferror(INDEX(Drivers!$C$11:$N$13,MATCH($C18,Drivers!$B$11:$B$13,0),MATCH(min(((year(N$1)-YEAR($D18))*12+MONTH(N$1)-MONTH($D18)),12),Drivers!$C$10:$N$10))))} | ... AD18: {=if(AND($E18<AD$1,$E18<>0),0,iferror(INDEX(Drivers!$C$11:$N$13,MATCH($C18,Drivers!$B$11:$B$13,0),MATCH(min(((year(AD$1)-YEAR($D18))*12+MONTH(AD$1)-MONTH($D18)),12),Drivers!$C$10:$N$10))))} -> 1
C19: Account Executives - Enterprise | D19: 45352 | E19: 1/0/00 | G19: {=if(AND($E19<G$1,$E19<>0),0,iferror(INDEX(Drivers!$C$11:$N$13,MATCH($C19,Drivers!$B$11:$B$13,0),MATCH(min(((year(G$1)-YEAR($D19))*12+MONTH(G$1)-MONTH($D19)),12),Drivers!$C$10:$N$10))))} | H19: {=if(AND($E19<H$1,$E19<>0),0,iferror(INDEX(Drivers!$C$11:$N$13,MATCH($C19,Drivers!$B$11:$B$13,0),MATCH(min(((year(H$1)-YEAR($D19))*12+MONTH(H$1)-MONTH($D19)),12),Drivers!$C$10:$N$10))))} | I19: {=if(AND($E19<I$1,$E19<>0),0,iferror(INDEX(Drivers!$C$11:$N$13,MATCH($C19,Drivers!$B$11:$B$13,0),MATCH(min(((year(I$1)-YEAR($D19))*12+MONTH(I$1)-MONTH($D19)),12),Drivers!$C$10:$N$10))))} -> 0 | J19: {=if(AND($E19<J$1,$E19<>0),0,iferror(INDEX(Drivers!$C$11:$N$13,MATCH($C19,Drivers!$B$11:$B$13,0),MATCH(min(((year(J$1)-YEAR($D19))*12+MONTH(J$1)-MONTH($D19)),12),Drivers!$C$10:$N$10))))} -> 0 | K19: {=if(AND($E19<K$1,$E19<>0),0,iferror(INDEX(Drivers!$C$11:$N$13,MATCH($C19,Drivers!$B$11:$B$13,0),MATCH(min(((year(K$1)-YEAR($D19))*12+MONTH(K$1)-MONTH($D19)),12),Drivers!$C$10:$N$10))))} -> 0 | L19: {=if(AND($E19<L$1,$E19<>0),0,iferror(INDEX(Drivers!$C$11:$N$13,MATCH($C19,Drivers!$B$11:$B$13,0),MATCH(min(((year(L$1)-YEAR($D19))*12+MONTH(L$1)-MONTH($D19)),12),Drivers!$C$10:$N$10))))} -> 0.25 | M19: {=if(AND($E19<M$1,$E19<>0),0,iferror(INDEX(Drivers!$C$11:$N$13,MATCH($C19,Drivers!$B$11:$B$13,0),MATCH(min(((year(M$1)-YEAR($D19))*12+MONTH(M$1)-MONTH($D19)),12),Drivers!$C$10:$N$10))))} -> 0.5 | N19: {=if(AND($E19<N$1,$E19<>0),0,iferror(INDEX(Drivers!$C$11:$N$13,MATCH($C19,Drivers!$B$11:$B$13,0),MATCH(min(((year(N$1)-YEAR($D19))*12+MONTH(N$1)-MONTH($D19)),12),Drivers!$C$10:$N$10))))} -> 0.5 | ... AD19: {=if(AND($E19<AD$1,$E19<>0),0,iferror(INDEX(Drivers!$C$11:$N$13,MATCH($C19,Drivers!$B$11:$B$13,0),MATCH(min(((year(AD$1)-YEAR($D19))*12+MONTH(AD$1)-MONTH($D19)),12),Drivers!$C$10:$N$10))))} -> 1
C20: Account Executives - Enterprise | D20: 45383 | E20: 1/0/00 | G20: {=if(AND($E20<G$1,$E20<>0),0,iferror(INDEX(Drivers!$C$11:$N$13,MATCH($C20,Drivers!$B$11:$B$13,0),MATCH(min(((year(G$1)-YEAR($D20))*12+MONTH(G$1)-MONTH($D20)),12),Drivers!$C$10:$N$10))))} | H20: {=if(AND($E20<H$1,$E20<>0),0,iferror(INDEX(Drivers!$C$11:$N$13,MATCH($C20,Drivers!$B$11:$B$13,0),MATCH(min(((year(H$1)-YEAR($D20))*12+MONTH(H$1)-MONTH($D20)),12),Drivers!$C$10:$N$10))))} | I20: {=if(AND($E20<I$1,$E20<>0),0,iferror(INDEX(Drivers!$C$11:$N$13,MATCH($C20,Drivers!$B$11:$B$13,0),MATCH(min(((year(I$1)-YEAR($D20))*12+MONTH(I$1)-MONTH($D20)),12),Drivers!$C$10:$N$10))))} | J20: {=if(AND($E20<J$1,$E20<>0),0,iferror(INDEX(Drivers!$C$11:$N$13,MATCH($C20,Drivers!$B$11:$B$13,0),MATCH(min(((year(J$1)-YEAR($D20))*12+MONTH(J$1)-MONTH($D20)),12),Drivers!$C$10:$N$10))))} -> 0 | K20: {=if(AND($E20<K$1,$E20<>0),0,iferror(INDEX(Drivers!$C$11:$N$13,MATCH($C20,Drivers!$B$11:$B$13,0),MATCH(min(((year(K$1)-YEAR($D20))*12+MONTH(K$1)-MONTH($D20)),12),Drivers!$C$10:$N$10))))} -> 0 | L20: {=if(AND($E20<L$1,$E20<>0),0,iferror(INDEX(Drivers!$C$11:$N$13,MATCH($C20,Drivers!$B$11:$B$13,0),MATCH(min(((year(L$1)-YEAR($D20))*12+MONTH(L$1)-MONTH($D20)),12),Drivers!$C$10:$N$10))))} -> 0 | M20: {=if(AND($E20<M$1,$E20<>0),0,iferror(INDEX(Drivers!$C$11:$N$13,MATCH($C20,Drivers!$B$11:$B$13,0),MATCH(min(((year(M$1)-YEAR($D20))*12+MONTH(M$1)-MONTH($D20)),12),Drivers!$C$10:$N$10))))} -> 0.25 | N20: {=if(AND($E20<N$1,$E20<>0),0,iferror(INDEX(Drivers!$C$11:$N$13,MATCH($C20,Drivers!$B$11:$B$13,0),MATCH(min(((year(N$1)-YEAR($D20))*12+MONTH(N$1)-MONTH($D20)),12),Drivers!$C$10:$N$10))))} -> 0.5 | ... AD20: {=if(AND($E20<AD$1,$E20<>0),0,iferror(INDEX(Drivers!$C$11:$N$13,MATCH($C20,Drivers!$B$11:$B$13,0),MATCH(min(((year(AD$1)-YEAR($D20))*12+MONTH(AD$1)-MONTH($D20)),12),Drivers!$C$10:$N$10))))} -> 1
C21: Account Executives - Enterprise | D21: 45413 | E21: 1/0/00 | G21: {=if(AND($E21<G$1,$E21<>0),0,iferror(INDEX(Drivers!$C$11:$N$13,MATCH($C21,Drivers!$B$11:$B$13,0),MATCH(min(((year(G$1)-YEAR($D21))*12+MONTH(G$1)-MONTH($D21)),12),Drivers!$C$10:$N$10))))} | H21: {=if(AND($E21<H$1,$E21<>0),0,iferror(INDEX(Drivers!$C$11:$N$13,MATCH($C21,Drivers!$B$11:$B$13,0),MATCH(min(((year(H$1)-YEAR($D21))*12+MONTH(H$1)-MONTH($D21)),12),Drivers!$C$10:$N$10))))} | I21: {=if(AND($E21<I$1,$E21<>0),0,iferror(INDEX(Drivers!$C$11:$N$13,MATCH($C21,Drivers!$B$11:$B$13,0),MATCH(min(((year(I$1)-YEAR($D21))*12+MONTH(I$1)-MONTH($D21)),12),Drivers!$C$10:$N$10))))} | J21: {=if(AND($E21<J$1,$E21<>0),0,iferror(INDEX(Drivers!$C$11:$N$13,MATCH($C21,Drivers!$B$11:$B$13,0),MATCH(min(((year(J$1)-YEAR($D21))*12+MONTH(J$1)-MONTH($D21)),12),Drivers!$C$10:$N$10))))} | K21: {=if(AND($E21<K$1,$E21<>0),0,iferror(INDEX(Drivers!$C$11:$N$13,MATCH($C21,Drivers!$B$11:$B$13,0),MATCH(min(((year(K$1)-YEAR($D21))*12+MONTH(K$1)-MONTH($D21)),12),Drivers!$C$10:$N$10))))} -> 0 | L21: {=if(AND($E21<L$1,$E21<>0),0,iferror(INDEX(Drivers!$C$11:$N$13,MATCH($C21,Drivers!$B$11:$B$13,0),MATCH(min(((year(L$1)-YEAR($D21))*12+MONTH(L$1)-MONTH($D21)),12),Drivers!$C$10:$N$10))))} -> 0 | M21: {=if(AND($E21<M$1,$E21<>0),0,iferror(INDEX(Drivers!$C$11:$N$13,MATCH($C21,Drivers!$B$11:$B$13,0),MATCH(min(((year(M$1)-YEAR($D21))*12+MONTH(M$1)-MONTH($D21)),12),Drivers!$C$10:$N$10))))} -> 0 | N21: {=if(AND($E21<N$1,$E21<>0),0,iferror(INDEX(Drivers!$C$11:$N$13,MATCH($C21,Drivers!$B$11:$B$13,0),MATCH(min(((year(N$1)-YEAR($D21))*12+MONTH(N$1)-MONTH($D21)),12),Drivers!$C$10:$N$10))))} -> 0.25 | ... AD21: {=if(AND($E21<AD$1,$E21<>0),0,iferror(INDEX(Drivers!$C$11:$N$13,MATCH($C21,Drivers!$B$11:$B$13,0),MATCH(min(((year(AD$1)-YEAR($D21))*12+MONTH(AD$1)-MONTH($D21)),12),Drivers!$C$10:$N$10))))} -> 1
G22: {=if(AND($E22<G$1,$E22<>0),0,iferror(INDEX(Drivers!$C$11:$N$13,MATCH($C24,Drivers!$B$11:$B$13,0),MATCH(min(((year(G$1)-YEAR($D22))*12+MONTH(G$1)-MONTH($D22)),12),Drivers!$C$10:$N$10))))} -> 1 | H22: {=if(AND($E22<H$1,$E22<>0),0,iferror(INDEX(Drivers!$C$11:$N$13,MATCH($C24,Drivers!$B$11:$B$13,0),MATCH(min(((year(H$1)-YEAR($D22))*12+MONTH(H$1)-MONTH($D22)),12),Drivers!$C$10:$N$10))))} -> 1 | I22: {=if(AND($E22<I$1,$E22<>0),0,iferror(INDEX(Drivers!$C$11:$N$13,MATCH($C24,Drivers!$B$11:$B$13,0),MATCH(min(((year(I$1)-YEAR($D22))*12+MONTH(I$1)-MONTH($D22)),12),Drivers!$C$10:$N$10))))} -> 1 | J22: {=if(AND($E22<J$1,$E22<>0),0,iferror(INDEX(Drivers!$C$11:$N$13,MATCH($C24,Drivers!$B$11:$B$13,0),MATCH(min(((year(J$1)-YEAR($D22))*12+MONTH(J$1)-MONTH($D22)),12),Drivers!$C$10:$N$10))))} -> 1 | K22: {=if(AND($E22<K$1,$E22<>0),0,iferror(INDEX(Drivers!$C$11:$N$13,MATCH($C24,Drivers!$B$11:$B$13,0),MATCH(min(((year(K$1)-YEAR($D22))*12+MONTH(K$1)-MONTH($D22)),12),Drivers!$C$10:$N$10))))} -> 1 | L22: {=if(AND($E22<L$1,$E22<>0),0,iferror(INDEX(Drivers!$C$11:$N$13,MATCH($C24,Drivers!$B$11:$B$13,0),MATCH(min(((year(L$1)-YEAR($D22))*12+MONTH(L$1)-MONTH($D22)),12),Drivers!$C$10:$N$10))))} -> 1 | M22: {=if(AND($E22<M$1,$E22<>0),0,iferror(INDEX(Drivers!$C$11:$N$13,MATCH($C24,Drivers!$B$11:$B$13,0),MATCH(min(((year(M$1)-YEAR($D22))*12+MONTH(M$1)-MONTH($D22)),12),Drivers!$C$10:$N$10))))} -> 1 | N22: {=if(AND($E22<N$1,$E22<>0),0,iferror(INDEX(Drivers!$C$11:$N$13,MATCH($C24,Drivers!$B$11:$B$13,0),MATCH(min(((year(N$1)-YEAR($D22))*12+MONTH(N$1)-MONTH($D22)),12),Drivers!$C$10:$N$10))))} -> 1 | ... AD22: {=if(AND($E22<AD$1,$E22<>0),0,iferror(INDEX(Drivers!$C$11:$N$13,MATCH($C24,Drivers!$B$11:$B$13,0),MATCH(min(((year(AD$1)-YEAR($D22))*12+MONTH(AD$1)-MONTH($D22)),12),Drivers!$C$10:$N$10))))} -> 1
C24: Account Executives - Enterprise | G24: =SUMIFS(G$5:G$22,$C$5:$C$22,$C24) -> 2.25 | H24: =SUMIFS(H$5:H$22,$C$5:$C$22,$C24) -> 2.5 | I24: =SUMIFS(I$5:I$22,$C$5:$C$22,$C24) -> 2.5 | J24: =SUMIFS(J$5:J$22,$C$5:$C$22,$C24) -> 3 | K24: =SUMIFS(K$5:K$22,$C$5:$C$22,$C24) -> 3.25 | L24: =SUMIFS(L$5:L$22,$C$5:$C$22,$C24) -> 3.75 | M24: =SUMIFS(M$5:M$22,$C$5:$C$22,$C24) -> 4.5 | N24: =SUMIFS(N$5:N$22,$C$5:$C$22,$C24) -> 5 | ... AD24: =SUMIFS(AD$5:AD$22,$C$5:$C$22,$C24) -> 7
C25: Account Executives - Mid Market | G25: =SUMIFS(G$5:G$22,$C$5:$C$22,$C25) -> 4 | H25: =SUMIFS(H$5:H$22,$C$5:$C$22,$C25) -> 4.5 | I25: =SUMIFS(I$5:I$22,$C$5:$C$22,$C25) -> 5.25 | J25: =SUMIFS(J$5:J$22,$C$5:$C$22,$C25) -> 6 | K25: =SUMIFS(K$5:K$22,$C$5:$C$22,$C25) -> 5.75 | L25: =SUMIFS(L$5:L$22,$C$5:$C$22,$C25) -> 6 | M25: =SUMIFS(M$5:M$22,$C$5:$C$22,$C25) -> 6 | N25: =SUMIFS(N$5:N$22,$C$5:$C$22,$C25) -> 6 | ... AD25: =SUMIFS(AD$5:AD$22,$C$5:$C$22,$C25) -> 6
C26: Account Executives - SMB | G26: =SUMIFS(G$5:G$22,$C$5:$C$22,$C26) -> 0 | H26: =SUMIFS(H$5:H$22,$C$5:$C$22,$C26) -> 0 | I26: =SUMIFS(I$5:I$22,$C$5:$C$22,$C26) -> 0 | J26: =SUMIFS(J$5:J$22,$C$5:$C$22,$C26) -> 0.5 | K26: =SUMIFS(K$5:K$22,$C$5:$C$22,$C26) -> 0.75 | L26: =SUMIFS(L$5:L$22,$C$5:$C$22,$C26) -> 1 | M26: =SUMIFS(M$5:M$22,$C$5:$C$22,$C26) -> 1 | N26: =SUMIFS(N$5:N$22,$C$5:$C$22,$C26) -> 1 | ... AD26: =SUMIFS(AD$5:AD$22,$C$5:$C$22,$C26) -> 2
C27: Total | G27: =G25+G24 -> 6.25 | H27: =H25+H24 -> 7 | I27: =I25+I24 -> 7.75 | J27: =J25+J24 -> 9 | K27: =K25+K24 -> 9 | L27: =L25+L24 -> 9.75 | M27: =M25+M24 -> 10.5 | N27: =N25+N24 -> 11 | ... AD27: =AD25+AD24 -> 13
B29: Street Quota
B31: =B5 -> OnlyCFO | C31: =C5 -> Account Executives - Enterprise | D31: =D5 -> 44562 | E31: =E5 -> 1/0/00 | G31: {=IFERROR((INDEX(Drivers!$B$5:$C$7,MATCH($C31,Drivers!$B$5:$B$7,0),2)))*G5*INDEX(Drivers!$C$24:$N$24,MATCH(LEFT(G$2,4),Drivers!$C$23:$N$23,0))} -> 72000 | H31: {=IFERROR((INDEX(Drivers!$B$5:$C$7,MATCH($C31,Drivers!$B$5:$B$7,0),2)))*H5*INDEX(Drivers!$C$24:$N$24,MATCH(LEFT(H$2,4),Drivers!$C$23:$N$23,0))} -> 72000 | I31: {=IFERROR((INDEX(Drivers!$B$5:$C$7,MATCH($C31,Drivers!$B$5:$B$7,0),2)))*I5*INDEX(Drivers!$C$24:$N$24,MATCH(LEFT(I$2,4),Drivers!$C$23:$N$23,0))} -> 96000 | J31: {=IFERROR((INDEX(Drivers!$B$5:$C$7,MATCH($C31,Drivers!$B$5:$B$7,0),2)))*J5*INDEX(Drivers!$C$24:$N$24,MATCH(LEFT(J$2,4),Drivers!$C$23:$N$23,0))} -> 72000 | K31: {=IFERROR((INDEX(Drivers!$B$5:$C$7,MATCH($C31,Drivers!$B$5:$B$7,0),2)))*K5*INDEX(Drivers!$C$24:$N$24,MATCH(LEFT(K$2,4),Drivers!$C$23:$N$23,0))} -> 72000 | L31: {=IFERROR((INDEX(Drivers!$B$5:$C$7,MATCH($C31,Drivers!$B$5:$B$7,0),2)))*L5*INDEX(Drivers!$C$24:$N$24,MATCH(LEFT(L$2,4),Drivers!$C$23:$N$23,0))} -> 96000 | M31: {=IFERROR((INDEX(Drivers!$B$5:$C$7,MATCH($C31,Drivers!$B$5:$B$7,0),2)))*M5*INDEX(Drivers!$C$24:$N$24,MATCH(LEFT(M$2,4),Drivers!$C$23:$N$23,0))} -> 90000 | N31: {=IFERROR((INDEX(Drivers!$B$5:$C$7,MATCH($C31,Drivers!$B$5:$B$7,0),2)))*N5*INDEX(Drivers!$C$24:$N$24,MATCH(LEFT(N$2,4),Drivers!$C$23:$N$23,0))} -> 90000 | ... AD31: {=IFERROR((INDEX(Drivers!$B$5:$C$7,MATCH($C31,Drivers!$B$5:$B$7,0),2)))*AD5*INDEX(Drivers!$C$24:$N$24,MATCH(LEFT(AD$2,4),Drivers!$C$23:$N$23,0))} -> 168000
B32: =B6 -> Bob | C32: =C6 -> Account Executives - Mid Market | D32: =D6 -> 44652 | E32: =E6 -> 1/0/00 | G32: {=IFERROR((INDEX(Drivers!$B$5:$C$7,MATCH($C32,Drivers!$B$5:$B$7,0),2)))*G6*INDEX(Drivers!$C$24:$N$24,MATCH(LEFT(G$2,4),Drivers!$C$23:$N$23,0))} -> 36000 | H32: {=IFERROR((INDEX(Drivers!$B$5:$C$7,MATCH($C32,Drivers!$B$5:$B$7,0),2)))*H6*INDEX(Drivers!$C$24:$N$24,MATCH(LEFT(H$2,4),Drivers!$C$23:$N$23,0))} -> 36000 | I32: {=IFERROR((INDEX(Drivers!$B$5:$C$7,MATCH($C32,Drivers!$B$5:$B$7,0),2)))*I6*INDEX(Drivers!$C$24:$N$24,MATCH(LEFT(I$2,4),Drivers!$C$23:$N$23,0))} -> 48000 | J32: {=IFERROR((INDEX(Drivers!$B$5:$C$7,MATCH($C32,Drivers!$B$5:$B$7,0),2)))*J6*INDEX(Drivers!$C$24:$N$24,MATCH(LEFT(J$2,4),Drivers!$C$23:$N$23,0))} -> 36000 | K32: {=IFERROR((INDEX(Drivers!$B$5:$C$7,MATCH($C32,Drivers!$B$5:$B$7,0),2)))*K6*INDEX(Drivers!$C$24:$N$24,MATCH(LEFT(K$2,4),Drivers!$C$23:$N$23,0))} -> 36000 | L32: {=IFERROR((INDEX(Drivers!$B$5:$C$7,MATCH($C32,Drivers!$B$5:$B$7,0),2)))*L6*INDEX(Drivers!$C$24:$N$24,MATCH(LEFT(L$2,4),Drivers!$C$23:$N$23,0))} -> 48000 | M32: {=IFERROR((INDEX(Drivers!$B$5:$C$7,MATCH($C32,Drivers!$B$5:$B$7,0),2)))*M6*INDEX(Drivers!$C$24:$N$24,MATCH(LEFT(M$2,4),Drivers!$C$23:$N$23,0))} -> 45000 | N32: {=IFERROR((INDEX(Drivers!$B$5:$C$7,MATCH($C32,Drivers!$B$5:$B$7,0),2)))*N6*INDEX(Drivers!$C$24:$N$24,MATCH(LEFT(N$2,4),Drivers!$C$23:$N$23,0))} -> 45000 | ... AD32: {=IFERROR((INDEX(Drivers!$B$5:$C$7,MATCH($C32,Drivers!$B$5:$B$7,0),2)))*AD6*INDEX(Drivers!$C$24:$N$24,MATCH(LEFT(AD$2,4),Drivers!$C$23:$N$23,0))} -> 84000
B33: =B7 -> John | C33: =C7 -> Account Executives - Enterprise | D33: =D7 -> 44835 | E33: =E7 -> 1/0/00 | G33: {=IFERROR((INDEX(Drivers!$B$5:$C$7,MATCH($C33,Drivers!$B$5:$B$7,0),2)))*G7*INDEX(Drivers!$C$24:$N$24,MATCH(LEFT(G$2,4),Drivers!$C$23:$N$23,0))} -> 72000 | H33: {=IFERROR((INDEX(Drivers!$B$5:$C$7,MATCH($C33,Drivers!$B$5:$B$7,0),2)))*H7*INDEX(Drivers!$C$24:$N$24,MATCH(LEFT(H$2,4),Drivers!$C$23:$N$23,0))} -> 72000 | I33: {=IFERROR((INDEX(Drivers!$B$5:$C$7,MATCH($C33,Drivers!$B$5:$B$7,0),2)))*I7*INDEX(Drivers!$C$24:$N$24,MATCH(LEFT(I$2,4),Drivers!$C$23:$N$23,0))} -> 96000 | J33: {=IFERROR((INDEX(Drivers!$B$5:$C$7,MATCH($C33,Drivers!$B$5:$B$7,0),2)))*J7*INDEX(Drivers!$C$24:$N$24,MATCH(LEFT(J$2,4),Drivers!$C$23:$N$23,0))} -> 72000 | K33: {=IFERROR((INDEX(Drivers!$B$5:$C$7,MATCH($C33,Drivers!$B$5:$B$7,0),2)))*K7*INDEX(Drivers!$C$24:$N$24,MATCH(LEFT(K$2,4),Drivers!$C$23:$N$23,0))} -> 72000 | L33: {=IFERROR((INDEX(Drivers!$B$5:$C$7,MATCH($C33,Drivers!$B$5:$B$7,0),2)))*L7*INDEX(Drivers!$C$24:$N$24,MATCH(LEFT(L$2,4),Drivers!$C$23:$N$23,0))} -> 96000 | M33: {=IFERROR((INDEX(Drivers!$B$5:$C$7,MATCH($C33,Drivers!$B$5:$B$7,0),2)))*M7*INDEX(Drivers!$C$24:$N$24,MATCH(LEFT(M$2,4),Drivers!$C$23:$N$23,0))} -> 90000 | N33: {=IFERROR((INDEX(Drivers!$B$5:$C$7,MATCH($C33,Drivers!$B$5:$B$7,0),2)))*N7*INDEX(Drivers!$C$24:$N$24,MATCH(LEFT(N$2,4),Drivers!$C$23:$N$23,0))} -> 90000 | ... AD33: {=IFERROR((INDEX(Drivers!$B$5:$C$7,MATCH($C33,Drivers!$B$5:$B$7,0),2)))*AD7*INDEX(Drivers!$C$24:$N$24,MATCH(LEFT(AD$2,4),Drivers!$C$23:$N$23,0))} -> 168000
B34: =B8 -> CJ | C34: =C8 -> Account Executives - Enterprise | D34: =D8 -> 44986 | E34: =E8 -> 45323 | G34: {=IFERROR((INDEX(Drivers!$B$5:$C$7,MATCH($C34,Drivers!$B$5:$B$7,0),2)))*G8*INDEX(Drivers!$C$24:$N$24,MATCH(LEFT(G$2,4),Drivers!$C$23:$N$23,0))} -> 0 | H34: {=IFERROR((INDEX(Drivers!$B$5:$C$7,MATCH($C34,Drivers!$B$5:$B$7,0),2)))*H8*INDEX(Drivers!$C$24:$N$24,MATCH(LEFT(H$2,4),Drivers!$C$23:$N$23,0))} -> 0 | I34: {=IFERROR((INDEX(Drivers!$B$5:$C$7,MATCH($C34,Drivers!$B$5:$B$7,0),2)))*I8*INDEX(Drivers!$C$24:$N$24,MATCH(LEFT(I$2,4),Drivers!$C$23:$N$23,0))} -> 0 | J34: {=IFERROR((INDEX(Drivers!$B$5:$C$7,MATCH($C34,Drivers!$B$5:$B$7,0),2)))*J8*INDEX(Drivers!$C$24:$N$24,MATCH(LEFT(J$2,4),Drivers!$C$23:$N$23,0))} -> 0 | K34: {=IFERROR((INDEX(Drivers!$B$5:$C$7,MATCH($C34,Drivers!$B$5:$B$7,0),2)))*K8*INDEX(Drivers!$C$24:$N$24,MATCH(LEFT(K$2,4),Drivers!$C$23:$N$23,0))} -> 0 | L34: {=IFERROR((INDEX(Drivers!$B$5:$C$7,MATCH($C34,Drivers!$B$5:$B$7,0),2)))*L8*INDEX(Drivers!$C$24:$N$24,MATCH(LEFT(L$2,4),Drivers!$C$23:$N$23,0))} -> 0 | M34: {=IFERROR((INDEX(Drivers!$B$5:$C$7,MATCH($C34,Drivers!$B$5:$B$7,0),2)))*M8*INDEX(Drivers!$C$24:$N$24,MATCH(LEFT(M$2,4),Drivers!$C$23:$N$23,0))} -> 0 | N34: {=IFERROR((INDEX(Drivers!$B$5:$C$7,MATCH($C34,Drivers!$B$5:$B$7,0),2)))*N8*INDEX(Drivers!$C$24:$N$24,MATCH(LEFT(N$2,4),Drivers!$C$23:$N$23,0))} -> 0 | ... AD34: {=IFERROR((INDEX(Drivers!$B$5:$C$7,MATCH($C34,Drivers!$B$5:$B$7,0),2)))*AD8*INDEX(Drivers!$C$24:$N$24,MATCH(LEFT(AD$2,4),Drivers!$C$23:$N$23,0))} -> 0
B35: =B9 -> SecretCFO | C35: =C9 -> Account Executives - Mid Market | D35: =D9 -> 44713 | E35: =E9 -> 1/0/00 | G35: {=IFERROR((INDEX(Drivers!$B$5:$C$7,MATCH($C35,Drivers!$B$5:$B$7,0),2)))*G9*INDEX(Drivers!$C$24:$N$24,MATCH(LEFT(G$2,4),Drivers!$C$23:$N$23,0))} -> 36000 | H35: {=IFERROR((INDEX(Drivers!$B$5:$C$7,MATCH($C35,Drivers!$B$5:$B$7,0),2)))*H9*INDEX(Drivers!$C$24:$N$24,MATCH(LEFT(H$2,4),Drivers!$C$23:$N$23,0))} -> 36000 | I35: {=IFERROR((INDEX(Drivers!$B$5:$C$7,MATCH($C35,Drivers!$B$5:$B$7,0),2)))*I9*INDEX(Drivers!$C$24:$N$24,MATCH(LEFT(I$2,4),Drivers!$C$23:$N$23,0))} -> 48000 | J35: {=IFERROR((INDEX(Drivers!$B$5:$C$7,MATCH($C35,Drivers!$B$5:$B$7,0),2)))*J9*INDEX(Drivers!$C$24:$N$24,MATCH(LEFT(J$2,4),Drivers!$C$23:$N$23,0))} -> 36000 | K35: {=IFERROR((INDEX(Drivers!$B$5:$C$7,MATCH($C35,Drivers!$B$5:$B$7,0),2)))*K9*INDEX(Drivers!$C$24:$N$24,MATCH(LEFT(K$2,4),Drivers!$C$23:$N$23,0))} -> 36000 | L35: {=IFERROR((INDEX(Drivers!$B$5:$C$7,MATCH($C35,Drivers!$B$5:$B$7,0),2)))*L9*INDEX(Drivers!$C$24:$N$24,MATCH(LEFT(L$2,4),Drivers!$C$23:$N$23,0))} -> 48000 | M35: {=IFERROR((INDEX(Drivers!$B$5:$C$7,MATCH($C35,Drivers!$B$5:$B$7,0),2)))*M9*INDEX(Drivers!$C$24:$N$24,MATCH(LEFT(M$2,4),Drivers!$C$23:$N$23,0))} -> 45000 | N35: {=IFERROR((INDEX(Drivers!$B$5:$C$7,MATCH($C35,Drivers!$B$5:$B$7,0),2)))*N9*INDEX(Drivers!$C$24:$N$24,MATCH(LEFT(N$2,4),Drivers!$C$23:$N$23,0))} -> 45000 | ... AD35: {=IFERROR((INDEX(Drivers!$B$5:$C$7,MATCH($C35,Drivers!$B$5:$B$7,0),2)))*AD9*INDEX(Drivers!$C$24:$N$24,MATCH(LEFT(AD$2,4),Drivers!$C$23:$N$23,0))} -> 84000
B36: =B10 -> Dory | C36: =C10 -> Account Executives - Mid Market | D36: =D10 -> 44470 | E36: =E10 -> 45444 | G36: {=IFERROR((INDEX(Drivers!$B$5:$C$7,MATCH($C36,Drivers!$B$5:$B$7,0),2)))*G10*INDEX(Drivers!$C$24:$N$24,MATCH(LEFT(G$2,4),Drivers!$C$23:$N$23,0))} -> 36000 | H36: {=IFERROR((INDEX(Drivers!$B$5:$C$7,MATCH($C36,Drivers!$B$5:$B$7,0),2)))*H10*INDEX(Drivers!$C$24:$N$24,MATCH(LEFT(H$2,4),Drivers!$C$23:$N$23,0))} -> 36000 | I36: {=IFERROR((INDEX(Drivers!$B$5:$C$7,MATCH($C36,Drivers!$B$5:$B$7,0),2)))*I10*INDEX(Drivers!$C$24:$N$24,MATCH(LEFT(I$2,4),Drivers!$C$23:$N$23,0))} -> 48000 | J36: {=IFERROR((INDEX(Drivers!$B$5:$C$7,MATCH($C36,Drivers!$B$5:$B$7,0),2)))*J10*INDEX(Drivers!$C$24:$N$24,MATCH(LEFT(J$2,4),Drivers!$C$23:$N$23,0))} -> 36000 | K36: {=IFERROR((INDEX(Drivers!$B$5:$C$7,MATCH($C36,Drivers!$B$5:$B$7,0),2)))*K10*INDEX(Drivers!$C$24:$N$24,MATCH(LEFT(K$2,4),Drivers!$C$23:$N$23,0))} -> 0 | L36: {=IFERROR((INDEX(Drivers!$B$5:$C$7,MATCH($C36,Drivers!$B$5:$B$7,0),2)))*L10*INDEX(Drivers!$C$24:$N$24,MATCH(LEFT(L$2,4),Drivers!$C$23:$N$23,0))} -> 0 | M36: {=IFERROR((INDEX(Drivers!$B$5:$C$7,MATCH($C36,Drivers!$B$5:$B$7,0),2)))*M10*INDEX(Drivers!$C$24:$N$24,MATCH(LEFT(M$2,4),Drivers!$C$23:$N$23,0))} -> 0 | N36: {=IFERROR((INDEX(Drivers!$B$5:$C$7,MATCH($C36,Drivers!$B$5:$B$7,0),2)))*N10*INDEX(Drivers!$C$24:$N$24,MATCH(LEFT(N$2,4),Drivers!$C$23:$N$23,0))} -> 0 | ... AD36: {=IFERROR((INDEX(Drivers!$B$5:$C$7,MATCH($C36,Drivers!$B$5:$B$7,0),2)))*AD10*INDEX(Drivers!$C$24:$N$24,MATCH(LEFT(AD$2,4),Drivers!$C$23:$N$23,0))} -> 0
B37: =B11 -> Brittany | C37: =C11 -> Account Executives - Mid Market | D37: =D11 -> 45261 | E37: =E11 -> 1/0/00 | G37: {=IFERROR((INDEX(Drivers!$B$5:$C$7,MATCH($C37,Drivers!$B$5:$B$7,0),2)))*G11*INDEX(Drivers!$C$24:$N$24,MATCH(LEFT(G$2,4),Drivers!$C$23:$N$23,0))} -> 0 | H37: {=IFERROR((INDEX(Drivers!$B$5:$C$7,MATCH($C37,Drivers!$B$5:$B$7,0),2)))*H11*INDEX(Drivers!$C$24:$N$24,MATCH(LEFT(H$2,4),Drivers!$C$23:$N$23,0))} -> 9000 | I37: {=IFERROR((INDEX(Drivers!$B$5:$C$7,MATCH($C37,Drivers!$B$5:$B$7,0),2)))*I11*INDEX(Drivers!$C$24:$N$24,MATCH(LEFT(I$2,4),Drivers!$C$23:$N$23,0))} -> 24000 | J37: {=IFERROR((INDEX(Drivers!$B$5:$C$7,MATCH($C37,Drivers!$B$5:$B$7,0),2)))*J11*INDEX(Drivers!$C$24:$N$24,MATCH(LEFT(J$2,4),Drivers!$C$23:$N$23,0))} -> 27000 | K37: {=IFERROR((INDEX(Drivers!$B$5:$C$7,MATCH($C37,Drivers!$B$5:$B$7,0),2)))*K11*INDEX(Drivers!$C$24:$N$24,MATCH(LEFT(K$2,4),Drivers!$C$23:$N$23,0))} -> 36000 | L37: {=IFERROR((INDEX(Drivers!$B$5:$C$7,MATCH($C37,Drivers!$B$5:$B$7,0),2)))*L11*INDEX(Drivers!$C$24:$N$24,MATCH(LEFT(L$2,4),Drivers!$C$23:$N$23,0))} -> 48000 | M37: {=IFERROR((INDEX(Drivers!$B$5:$C$7,MATCH($C37,Drivers!$B$5:$B$7,0),2)))*M11*INDEX(Drivers!$C$24:$N$24,MATCH(LEFT(M$2,4),Drivers!$C$23:$N$23,0))} -> 45000 | N37: {=IFERROR((INDEX(Drivers!$B$5:$C$7,MATCH($C37,Drivers!$B$5:$B$7,0),2)))*N11*INDEX(Drivers!$C$24:$N$24,MATCH(LEFT(N$2,4),Drivers!$C$23:$N$23,0))} -> 45000 | ... AD37: {=IFERROR((INDEX(Drivers!$B$5:$C$7,MATCH($C37,Drivers!$B$5:$B$7,0),2)))*AD11*INDEX(Drivers!$C$24:$N$24,MATCH(LEFT(AD$2,4),Drivers!$C$23:$N$23,0))} -> 84000
B38: =B12 -> Dora the Explorer | C38: =C12 -> Account Executives - Enterprise | D38: =D12 -> 45321 | E38: =E12 -> 1/0/00 | G38: {=IFERROR((INDEX(Drivers!$B$5:$C$7,MATCH($C38,Drivers!$B$5:$B$7,0),2)))*G12*INDEX(Drivers!$C$24:$N$24,MATCH(LEFT(G$2,4),Drivers!$C$23:$N$23,0))} -> 0 | H38: {=IFERROR((INDEX(Drivers!$B$5:$C$7,MATCH($C38,Drivers!$B$5:$B$7,0),2)))*H12*INDEX(Drivers!$C$24:$N$24,MATCH(LEFT(H$2,4),Drivers!$C$23:$N$23,0))} -> 0 | I38: {=IFERROR((INDEX(Drivers!$B$5:$C$7,MATCH($C38,Drivers!$B$5:$B$7,0),2)))*I12*INDEX(Drivers!$C$24:$N$24,MATCH(LEFT(I$2,4),Drivers!$C$23:$N$23,0))} -> 0 | J38: {=IFERROR((INDEX(Drivers!$B$5:$C$7,MATCH($C38,Drivers!$B$5:$B$7,0),2)))*J12*INDEX(Drivers!$C$24:$N$24,MATCH(LEFT(J$2,4),Drivers!$C$23:$N$23,0))} -> 18000 | K38: {=IFERROR((INDEX(Drivers!$B$5:$C$7,MATCH($C38,Drivers!$B$5:$B$7,0),2)))*K12*INDEX(Drivers!$C$24:$N$24,MATCH(LEFT(K$2,4),Drivers!$C$23:$N$23,0))} -> 36000 | L38: {=IFERROR((INDEX(Drivers!$B$5:$C$7,MATCH($C38,Drivers!$B$5:$B$7,0),2)))*L12*INDEX(Drivers!$C$24:$N$24,MATCH(LEFT(L$2,4),Drivers!$C$23:$N$23,0))} -> 48000 | M38: {=IFERROR((INDEX(Drivers!$B$5:$C$7,MATCH($C38,Drivers!$B$5:$B$7,0),2)))*M12*INDEX(Drivers!$C$24:$N$24,MATCH(LEFT(M$2,4),Drivers!$C$23:$N$23,0))} -> 67500 | N38: {=IFERROR((INDEX(Drivers!$B$5:$C$7,MATCH($C38,Drivers!$B$5:$B$7,0),2)))*N12*INDEX(Drivers!$C$24:$N$24,MATCH(LEFT(N$2,4),Drivers!$C$23:$N$23,0))} -> 67500 | ... AD38: {=IFERROR((INDEX(Drivers!$B$5:$C$7,MATCH($C38,Drivers!$B$5:$B$7,0),2)))*AD12*INDEX(Drivers!$C$24:$N$24,MATCH(LEFT(AD$2,4),Drivers!$C$23:$N$23,0))} -> 168000
B39: =B13 -> Elsa | C39: =C13 -> Account Executives - Mid Market | D39: =D13 -> 45078 | E39: =E13 -> 1/0/00 | G39: {=IFERROR((INDEX(Drivers!$B$5:$C$7,MATCH($C39,Drivers!$B$5:$B$7,0),2)))*G13*INDEX(Drivers!$C$24:$N$24,MATCH(LEFT(G$2,4),Drivers!$C$23:$N$23,0))} -> 36000 | H39: {=IFERROR((INDEX(Drivers!$B$5:$C$7,MATCH($C39,Drivers!$B$5:$B$7,0),2)))*H13*INDEX(Drivers!$C$24:$N$24,MATCH(LEFT(H$2,4),Drivers!$C$23:$N$23,0))} -> 36000 | I39: {=IFERROR((INDEX(Drivers!$B$5:$C$7,MATCH($C39,Drivers!$B$5:$B$7,0),2)))*I13*INDEX(Drivers!$C$24:$N$24,MATCH(LEFT(I$2,4),Drivers!$C$23:$N$23,0))} -> 48000 | J39: {=IFERROR((INDEX(Drivers!$B$5:$C$7,MATCH($C39,Drivers!$B$5:$B$7,0),2)))*J13*INDEX(Drivers!$C$24:$N$24,MATCH(LEFT(J$2,4),Drivers!$C$23:$N$23,0))} -> 36000 | K39: {=IFERROR((INDEX(Drivers!$B$5:$C$7,MATCH($C39,Drivers!$B$5:$B$7,0),2)))*K13*INDEX(Drivers!$C$24:$N$24,MATCH(LEFT(K$2,4),Drivers!$C$23:$N$23,0))} -> 36000 | L39: {=IFERROR((INDEX(Drivers!$B$5:$C$7,MATCH($C39,Drivers!$B$5:$B$7,0),2)))*L13*INDEX(Drivers!$C$24:$N$24,MATCH(LEFT(L$2,4),Drivers!$C$23:$N$23,0))} -> 48000 | M39: {=IFERROR((INDEX(Drivers!$B$5:$C$7,MATCH($C39,Drivers!$B$5:$B$7,0),2)))*M13*INDEX(Drivers!$C$24:$N$24,MATCH(LEFT(M$2,4),Drivers!$C$23:$N$23,0))} -> 45000 | N39: {=IFERROR((INDEX(Drivers!$B$5:$C$7,MATCH($C39,Drivers!$B$5:$B$7,0),2)))*N13*INDEX(Drivers!$C$24:$N$24,MATCH(LEFT(N$2,4),Drivers!$C$23:$N$23,0))} -> 45000 | ... AD39: {=IFERROR((INDEX(Drivers!$B$5:$C$7,MATCH($C39,Drivers!$B$5:$B$7,0),2)))*AD13*INDEX(Drivers!$C$24:$N$24,MATCH(LEFT(AD$2,4),Drivers!$C$23:$N$23,0))} -> 84000
B40: =B14 -> Snow White | C40: =C14 -> Account Executives - Enterprise | D40: =D14 -> 45200 | E40: =E14 -> 1/0/00 | G40: {=IFERROR((INDEX(Drivers!$B$5:$C$7,MATCH($C40,Drivers!$B$5:$B$7,0),2)))*G14*INDEX(Drivers!$C$24:$N$24,MATCH(LEFT(G$2,4),Drivers!$C$23:$N$23,0))} -> 18000 | H40: {=IFERROR((INDEX(Drivers!$B$5:$C$7,MATCH($C40,Drivers!$B$5:$B$7,0),2)))*H14*INDEX(Drivers!$C$24:$N$24,MATCH(LEFT(H$2,4),Drivers!$C$23:$N$23,0))} -> 36000 | I40: {=IFERROR((INDEX(Drivers!$B$5:$C$7,MATCH($C40,Drivers!$B$5:$B$7,0),2)))*I14*INDEX(Drivers!$C$24:$N$24,MATCH(LEFT(I$2,4),Drivers!$C$23:$N$23,0))} -> 48000 | J40: {=IFERROR((INDEX(Drivers!$B$5:$C$7,MATCH($C40,Drivers!$B$5:$B$7,0),2)))*J14*INDEX(Drivers!$C$24:$N$24,MATCH(LEFT(J$2,4),Drivers!$C$23:$N$23,0))} -> 54000 | K40: {=IFERROR((INDEX(Drivers!$B$5:$C$7,MATCH($C40,Drivers!$B$5:$B$7,0),2)))*K14*INDEX(Drivers!$C$24:$N$24,MATCH(LEFT(K$2,4),Drivers!$C$23:$N$23,0))} -> 54000 | L40: {=IFERROR((INDEX(Drivers!$B$5:$C$7,MATCH($C40,Drivers!$B$5:$B$7,0),2)))*L14*INDEX(Drivers!$C$24:$N$24,MATCH(LEFT(L$2,4),Drivers!$C$23:$N$23,0))} -> 96000 | M40: {=IFERROR((INDEX(Drivers!$B$5:$C$7,MATCH($C40,Drivers!$B$5:$B$7,0),2)))*M14*INDEX(Drivers!$C$24:$N$24,MATCH(LEFT(M$2,4),Drivers!$C$23:$N$23,0))} -> 90000 | N40: {=IFERROR((INDEX(Drivers!$B$5:$C$7,MATCH($C40,Drivers!$B$5:$B$7,0),2)))*N14*INDEX(Drivers!$C$24:$N$24,MATCH(LEFT(N$2,4),Drivers!$C$23:$N$23,0))} -> 90000 | ... AD40: {=IFERROR((INDEX(Drivers!$B$5:$C$7,MATCH($C40,Drivers!$B$5:$B$7,0),2)))*AD14*INDEX(Drivers!$C$24:$N$24,MATCH(LEFT(AD$2,4),Drivers!$C$23:$N$23,0))} -> 168000
B41: =B15 | C41: =C15 -> Account Executives - Mid Market | D41: =D15 -> 45261 | E41: =E15 -> 1/0/00 | G41: {=IFERROR((INDEX(Drivers!$B$5:$C$7,MATCH($C41,Drivers!$B$5:$B$7,0),2)))*G15*INDEX(Drivers!$C$24:$N$24,MATCH(LEFT(G$2,4),Drivers!$C$23:$N$23,0))} -> 0 | H41: {=IFERROR((INDEX(Drivers!$B$5:$C$7,MATCH($C41,Drivers!$B$5:$B$7,0),2)))*H15*INDEX(Drivers!$C$24:$N$24,MATCH(LEFT(H$2,4),Drivers!$C$23:$N$23,0))} -> 9000 | I41: {=IFERROR((INDEX(Drivers!$B$5:$C$7,MATCH($C41,Drivers!$B$5:$B$7,0),2)))*I15*INDEX(Drivers!$C$24:$N$24,MATCH(LEFT(I$2,4),Drivers!$C$23:$N$23,0))} -> 24000 | J41: {=IFERROR((INDEX(Drivers!$B$5:$C$7,MATCH($C41,Drivers!$B$5:$B$7,0),2)))*J15*INDEX(Drivers!$C$24:$N$24,MATCH(LEFT(J$2,4),Drivers!$C$23:$N$23,0))} -> 27000 | K41: {=IFERROR((INDEX(Drivers!$B$5:$C$7,MATCH($C41,Drivers!$B$5:$B$7,0),2)))*K15*INDEX(Drivers!$C$24:$N$24,MATCH(LEFT(K$2,4),Drivers!$C$23:$N$23,0))} -> 36000 | L41: {=IFERROR((INDEX(Drivers!$B$5:$C$7,MATCH($C41,Drivers!$B$5:$B$7,0),2)))*L15*INDEX(Drivers!$C$24:$N$24,MATCH(LEFT(L$2,4),Drivers!$C$23:$N$23,0))} -> 48000 | M41: {=IFERROR((INDEX(Drivers!$B$5:$C$7,MATCH($C41,Drivers!$B$5:$B$7,0),2)))*M15*INDEX(Drivers!$C$24:$N$24,MATCH(LEFT(M$2,4),Drivers!$C$23:$N$23,0))} -> 45000 | N41: {=IFERROR((INDEX(Drivers!$B$5:$C$7,MATCH($C41,Drivers!$B$5:$B$7,0),2)))*N15*INDEX(Drivers!$C$24:$N$24,MATCH(LEFT(N$2,4),Drivers!$C$23:$N$23,0))} -> 45000 | ... AD41: {=IFERROR((INDEX(Drivers!$B$5:$C$7,MATCH($C41,Drivers!$B$5:$B$7,0),2)))*AD15*INDEX(Drivers!$C$24:$N$24,MATCH(LEFT(AD$2,4),Drivers!$C$23:$N$23,0))} -> 84000
